Workbook

Sheet 利益演示
C1: 中意真爱久久年金保险（关爱版A款）产品计划演示表
C2: 被保险人信息
B3: =VLOOKUP(F3, $O$3:$P$8, 2, 0) -> 10 | C3: 性别 | D3: 男 | E3: 交费期间 | F3: 10年交 | G3: 年龄 | H3: 30 | I3: =IF(H3>VLOOKUP(F3,保费保额表!$J$2:$K$7,2,FALSE),F3&"最大投保年龄为"&VLOOKUP(F3,保费保额表!$J$2:$K$7,2,FALSE)&"周岁，请重新选择","") | O3: 一次性付清 | P3: 1 | R3: 0 | S3: 1
B4: =B3&"_"&D3&"_"&H3 -> 10_男_30 | C4: 产品计划 | O4: 3年交 | P4: 3 | R4: 18 | S4: 1.6
C5: 中意真爱久久年金保险（关爱版A款） | E5: 首年保费 | F5: 100000 | G5: 基本保额 | H5: =OFFSET(保费保额表!G1, MATCH(B4, 保费保额表!B2:B747, 0), 0)*F5/1000 -> 24300 | I5: 总保费 | J5: =F5*B3 -> 1000000 | O5: 5年交 | P5: 5 | R5: 41 | S5: 1.4
O6: 10年交 | P6: 10 | R6: 61 | S6: 1.2
O7: 15年交 | P7: 15
O8: 20年交 | P8: 20
C15: 保单信息 | F15: 中意真爱久久年金保险（关爱版A款）
C16: 保单年度 | D16: 已达年龄 | E16: 年交保费 | F16: 已交保费 | G16: 年金 | H16: 养老年金 | I16: 现金价值 | J16: 身故保险金
C17: 1 | D17: =H3+1 -> 31 | E17: =IF(C17="","",IF(C17<=$B$3, $F$5, 0)) -> 100000 | F17: =IF(C17="", "", SUM($E$17:E17)) -> 100000 | G17: =IF(C17="", "", IF(AND(C17>=5, D17<60), $H$5, 0)) -> 0 | H17: =IF(C17="", "", IF(D17>=60, 2*$H$5, 0)) -> 0 | I17: =IF(C17="", "", ROUND($H$5/1000*OFFSET(现价表!$B$1, MATCH($B$4, 现价表!$B$2:$B$747, 0), C17+3), 0)) -> 38756 | J17: =IF(C17="", "", IF(D17<=60, MAX(F17, I17), MAX(2*$H$5*20-SUM(H$16:H16), 0))) -> 100000
C18: =IF(AND(C17>0, C17<99-$H$3), C17+1,"") -> 2 | D18: =IF(C18="","",D17+1) -> 32 | E18: =IF(C18="","",IF(C18<=$B$3, $F$5, 0)) -> 100000 | F18: =IF(C18="", "", SUM($E$17:E18)) -> 200000 | G18: =IF(C18="", "", IF(AND(C18>=5, D18<60), $H$5, 0)) -> 0 | H18: =IF(C18="", "", IF(D18>=60, 2*$H$5, 0)) -> 0 | I18: =IF(C18="", "", ROUND($H$5/1000*OFFSET(现价表!$B$1, MATCH($B$4, 现价表!$B$2:$B$747, 0), C18+3), 0)) -> 90097 | J18: =IF(C18="", "", IF(D18<=60, MAX(F18, I18), MAX(2*$H$5*20-SUM(H$16:H17), 0))) -> 200000
C19: =IF(AND(C18>0, C18<99-$H$3), C18+1,"") -> 3 | D19: =IF(C19="","",D18+1) -> 33 | E19: =IF(C19="","",IF(C19<=$B$3, $F$5, 0)) -> 100000 | F19: =IF(C19="", "", SUM($E$17:E19)) -> 300000 | G19: =IF(C19="", "", IF(AND(C19>=5, D19<60), $H$5, 0)) -> 0 | H19: =IF(C19="", "", IF(D19>=60, 2*$H$5, 0)) -> 0 | I19: =IF(C19="", "", ROUND($H$5/1000*OFFSET(现价表!$B$1, MATCH($B$4, 现价表!$B$2:$B$747, 0), C19+3), 0)) -> 151695 | J19: =IF(C19="", "", IF(D19<=60, MAX(F19, I19), MAX(2*$H$5*20-SUM(H$16:H18), 0))) -> 300000
C20: =IF(AND(C19>0, C19<99-$H$3), C19+1,"") -> 4 | D20: =IF(C20="","",D19+1) -> 34 | E20: =IF(C20="","",IF(C20<=$B$3, $F$5, 0)) -> 100000 | F20: =IF(C20="", "", SUM($E$17:E20)) -> 400000 | G20: =IF(C20="", "", IF(AND(C20>=5, D20<60), $H$5, 0)) -> 0 | H20: =IF(C20="", "", IF(D20>=60, 2*$H$5, 0)) -> 0 | I20: =IF(C20="", "", ROUND($H$5/1000*OFFSET(现价表!$B$1, MATCH($B$4, 现价表!$B$2:$B$747, 0), C20+3), 0)) -> 220972 | J20: =IF(C20="", "", IF(D20<=60, MAX(F20, I20), MAX(2*$H$5*20-SUM(H$16:H19), 0))) -> 400000
C21: =IF(AND(C20>0, C20<99-$H$3), C20+1,"") -> 5 | D21: =IF(C21="","",D20+1) -> 35 | E21: =IF(C21="","",IF(C21<=$B$3, $F$5, 0)) -> 100000 | F21: =IF(C21="", "", SUM($E$17:E21)) -> 500000 | G21: =IF(C21="", "", IF(AND(C21>=5, D21<60), $H$5, 0)) -> 24300 | H21: =IF(C21="", "", IF(D21>=60, 2*$H$5, 0)) -> 0 | I21: =IF(C21="", "", ROUND($H$5/1000*OFFSET(现价表!$B$1, MATCH($B$4, 现价表!$B$2:$B$747, 0), C21+3), 0)) -> 271992 | J21: =IF(C21="", "", IF(D21<=60, MAX(F21, I21), MAX(2*$H$5*20-SUM(H$16:H20), 0))) -> 500000
C22: =IF(AND(C21>0, C21<99-$H$3), C21+1,"") -> 6 | D22: =IF(C22="","",D21+1) -> 36 | E22: =IF(C22="","",IF(C22<=$B$3, $F$5, 0)) -> 100000 | F22: =IF(C22="", "", SUM($E$17:E22)) -> 600000 | G22: =IF(C22="", "", IF(AND(C22>=5, D22<60), $H$5, 0)) -> 24300 | H22: =IF(C22="", "", IF(D22>=60, 2*$H$5, 0)) -> 0 | I22: =IF(C22="", "", ROUND($H$5/1000*OFFSET(现价表!$B$1, MATCH($B$4, 现价表!$B$2:$B$747, 0), C22+3), 0)) -> 326444 | J22: =IF(C22="", "", IF(D22<=60, MAX(F22, I22), MAX(2*$H$5*20-SUM(H$16:H21), 0))) -> 600000
C23: =IF(AND(C22>0, C22<99-$H$3), C22+1,"") -> 7 | D23: =IF(C23="","",D22+1) -> 37 | E23: =IF(C23="","",IF(C23<=$B$3, $F$5, 0)) -> 100000 | F23: =IF(C23="", "", SUM($E$17:E23)) -> 700000 | G23: =IF(C23="", "", IF(AND(C23>=5, D23<60), $H$5, 0)) -> 24300 | H23: =IF(C23="", "", IF(D23>=60, 2*$H$5, 0)) -> 0 | I23: =IF(C23="", "", ROUND($H$5/1000*OFFSET(现价表!$B$1, MATCH($B$4, 现价表!$B$2:$B$747, 0), C23+3), 0)) -> 384518 | J23: =IF(C23="", "", IF(D23<=60, MAX(F23, I23), MAX(2*$H$5*20-SUM(H$16:H22), 0))) -> 700000
C24: =IF(AND(C23>0, C23<99-$H$3), C23+1,"") -> 8 | D24: =IF(C24="","",D23+1) -> 38 | E24: =IF(C24="","",IF(C24<=$B$3, $F$5, 0)) -> 100000 | F24: =IF(C24="", "", SUM($E$17:E24)) -> 800000 | G24: =IF(C24="", "", IF(AND(C24>=5, D24<60), $H$5, 0)) -> 24300 | H24: =IF(C24="", "", IF(D24>=60, 2*$H$5, 0)) -> 0 | I24: =IF(C24="", "", ROUND($H$5/1000*OFFSET(现价表!$B$1, MATCH($B$4, 现价表!$B$2:$B$747, 0), C24+3), 0)) -> 446418 | J24: =IF(C24="", "", IF(D24<=60, MAX(F24, I24), MAX(2*$H$5*20-SUM(H$16:H23), 0))) -> 800000
C25: =IF(AND(C24>0, C24<99-$H$3), C24+1,"") -> 9 | D25: =IF(C25="","",D24+1) -> 39 | E25: =IF(C25="","",IF(C25<=$B$3, $F$5, 0)) -> 100000 | F25: =IF(C25="", "", SUM($E$17:E25)) -> 900000 | G25: =IF(C25="", "", IF(AND(C25>=5, D25<60), $H$5, 0)) -> 24300 | H25: =IF(C25="", "", IF(D25>=60, 2*$H$5, 0)) -> 0 | I25: =IF(C25="", "", ROUND($H$5/1000*OFFSET(现价表!$B$1, MATCH($B$4, 现价表!$B$2:$B$747, 0), C25+3), 0)) -> 512353 | J25: =IF(C25="", "", IF(D25<=60, MAX(F25, I25), MAX(2*$H$5*20-SUM(H$16:H24), 0))) -> 900000
C26: =IF(AND(C25>0, C25<99-$H$3), C25+1,"") -> 10 | D26: =IF(C26="","",D25+1) -> 40 | E26: =IF(C26="","",IF(C26<=$B$3, $F$5, 0)) -> 100000 | F26: =IF(C26="", "", SUM($E$17:E26)) -> 1000000 | G26: =IF(C26="", "", IF(AND(C26>=5, D26<60), $H$5, 0)) -> 24300 | H26: =IF(C26="", "", IF(D26>=60, 2*$H$5, 0)) -> 0 | I26: =IF(C26="", "", ROUND($H$5/1000*OFFSET(现价表!$B$1, MATCH($B$4, 现价表!$B$2:$B$747, 0), C26+3), 0)) -> 582549 | J26: =IF(C26="", "", IF(D26<=60, MAX(F26, I26), MAX(2*$H$5*20-SUM(H$16:H25), 0))) -> 1000000
C27: =IF(AND(C26>0, C26<99-$H$3), C26+1,"") -> 11 | D27: =IF(C27="","",D26+1) -> 41 | E27: =IF(C27="","",IF(C27<=$B$3, $F$5, 0)) -> 0 | F27: =IF(C27="", "", SUM($E$17:E27)) -> 1000000 | G27: =IF(C27="", "", IF(AND(C27>=5, D27<60), $H$5, 0)) -> 24300 | H27: =IF(C27="", "", IF(D27>=60, 2*$H$5, 0)) -> 0 | I27: =IF(C27="", "", ROUND($H$5/1000*OFFSET(现价表!$B$1, MATCH($B$4, 现价表!$B$2:$B$747, 0), C27+3), 0)) -> 586847 | J27: =IF(C27="", "", IF(D27<=60, MAX(F27, I27), MAX(2*$H$5*20-SUM(H$16:H26), 0))) -> 1000000
C28: =IF(AND(C27>0, C27<99-$H$3), C27+1,"") -> 12 | D28: =IF(C28="","",D27+1) -> 42 | E28: =IF(C28="","",IF(C28<=$B$3, $F$5, 0)) -> 0 | F28: =IF(C28="", "", SUM($E$17:E28)) -> 1000000 | G28: =IF(C28="", "", IF(AND(C28>=5, D28<60), $H$5, 0)) -> 24300 | H28: =IF(C28="", "", IF(D28>=60, 2*$H$5, 0)) -> 0 | I28: =IF(C28="", "", ROUND($H$5/1000*OFFSET(现价表!$B$1, MATCH($B$4, 现价表!$B$2:$B$747, 0), C28+3), 0)) -> 591321 | J28: =IF(C28="", "", IF(D28<=60, MAX(F28, I28), MAX(2*$H$5*20-SUM(H$16:H27), 0))) -> 1000000
C29: =IF(AND(C28>0, C28<99-$H$3), C28+1,"") -> 13 | D29: =IF(C29="","",D28+1) -> 43 | E29: =IF(C29="","",IF(C29<=$B$3, $F$5, 0)) -> 0 | F29: =IF(C29="", "", SUM($E$17:E29)) -> 1000000 | G29: =IF(C29="", "", IF(AND(C29>=5, D29<60), $H$5, 0)) -> 24300 | H29: =IF(C29="", "", IF(D29>=60, 2*$H$5, 0)) -> 0 | I29: =IF(C29="", "", ROUND($H$5/1000*OFFSET(现价表!$B$1, MATCH($B$4, 现价表!$B$2:$B$747, 0), C29+3), 0)) -> 595977 | J29: =IF(C29="", "", IF(D29<=60, MAX(F29, I29), MAX(2*$H$5*20-SUM(H$16:H28), 0))) -> 1000000
... C121: =IF(AND(C120>0, C120<99-$H$3), C120+1,"") | D121: =IF(C121="","",D120+1) | E121: =IF(C121="","",IF(C121<=$B$3, $F$5, 0)) | F121: =IF(C121="", "", SUM($E$17:E121)) | G121: =IF(C121="", "", IF(AND(C121>=5, D121<60), $H$5, 0)) | H121: =IF(C121="", "", IF(D121>=60, 2*$H$5, 0)) | I121: =IF(C121="", "", ROUND($H$5/1000*OFFSET(现价表!$B$1, MATCH($B$4, 现价表!$B$2:$B$747, 0), C121+3), 0)) | J121: =IF(C121="", "", IF(D121<=60, MAX(F121, I121), MAX(2*$H$5*20-SUM(H$16:H120), 0)))

Sheet 利益演示-组合万能
C1: 中意真爱久久年金保险（关爱版A款）产品计划演示表
C2: 被保险人信息
B3: =VLOOKUP(F3, $O$3:$P$8, 2, 0) -> 10 | C3: 性别 | D3: =利益演示!D3 -> 男 | E3: 缴费期 | F3: =利益演示!F3 -> 10年交 | G3: 年龄 | H3: =利益演示!H3 -> 30 | I3: =IF(H3>VLOOKUP(F3,保费保额表!$J$2:$K$7,2,FALSE),F3&"最大投保年龄为"&VLOOKUP(F3,保费保额表!$J$2:$K$7,2,FALSE)&"周岁，请重新选择","") | O3: 一次性付清 | P3: 1 | R3: 已达年龄 | S3: 系数 | U3: 保单年度 | V3: 退保扣费
B4: =B3&"_"&D3&"_"&H3 -> 10_男_30 | C4: 产品计划 | O4: 3年交 | P4: 3 | R4: 0 | S4: 1 | U4: 1 | V4: 0.03
C5: 中意真爱久久年金保险（关爱版A款） | E5: 首年保费 | F5: =利益演示!F5 -> 100000 | G5: 基本保额 | H5: =利益演示!H5 -> 24300 | I5: 总保费 | J5: =利益演示!J5 -> 1000000 | O5: 5年交 | P5: 5 | R5: 18 | S5: 1.6 | U5: 2 | V5: 0.01
C6: 中意鑫意锁终身寿险（万能型） | E6: 一次性付清保费 | F6: 1000 | O6: 10年交 | P6: 10 | R6: 42 | S6: 1.4 | U6: 3 | V6: 0.01
O7: 15年交 | P7: 15 | R7: 62 | S7: 1.2 | U7: 4 | V7: 0.01
O8: 20年交 | P8: 20 | U8: 5 | V8: 0.01
U9: 6 | V9: 0
O14: =IF(MIN(Q18:OFFSET(Q18, 105-$H$3-1, 0))<=0, LEFT(O15, 4)&"下账户价值不支持此部分领取方案！", "") | T14: =IF(MIN(V18:OFFSET(V18, 105-$H$3-1, 0))<=0, LEFT(T15, 4)&"下账户价值不支持此部分领取方案！", "")
C15: 保单信息 | E15: 一次性付清保费 | F15: 定期追加保费 | G15: 不定期追加保费 | H15: 约定转入保费 | I15: 累计保险费 | J15: 初始费用 | K15: 持续奖励 | L15: 部分领取 | M15: 部分领取费用 | N15: 基本保额 | O15: 最低保证利益演示2.0% | T15: 万能结息利益演示4.0%
C16: 保单年度 | D16: 已达年龄 | F16: （手动输入） | G16: （手动输入） | L16: （手动输入） | O16: 期初账户价值 | P16: 风险保险费 | Q16: 期末账户价值 | R16: 现金价值 | S16: 身故保险金 | T16: 期初账户价值 | U16: 风险保险费 | V16: 期末账户价值 | W16: 现金价值 | X16: 身故保险金
C18: 1 | D18: =H3+1 -> 31 | E18: =IF(C18="", "", IF(C18=1, $F$6, 0)) -> 1000 | H18: =IF(C18="", "", IF(AND(C18>=6, D18<=60), OFFSET(利益演示!$G$16, C18-1, 0), IF(D18>60, OFFSET(利益演示!$H$16, C18-1, 0), 0))) -> 0 | I18: =IF(C18="", "", SUM($E$18:H18)) -> 1000 | J18: =IF(C18="","",E18*1%+F18*1%+G18*3%+H18*1%) -> 10 | K18: =IF(C18="", "", ROUND(IF(C18=6, SUM(OFFSET(H17, -4, 0):H17)*1%, IF(C18>6,H17*1%, 0)),0)) -> 0 | M18: =IF(C18="", "", L18*VLOOKUP(C18, $U$4:$V$9, 2)) -> 0 | N18: =IF(C18="", "", MAX(I18-SUM(L$17:L17), 0)) -> 1000 | O18: =IF($C18="", "", IF(AND($C18>1, Q17<=0), 0, Q17+SUM($E18:$H18)-$J18+K18)) -> 990 | P18: =IF($C18="", "", IF(O18<=0, 0, MAX(VLOOKUP($D18-1, $R$4:$S$7, 2)*$N18-O18, 0)*OFFSET(鑫意锁风险保险费!$B$5, $D18-1, IF($D$3="男", 1, 2))/1000)) -> 0.488 | Q18: =IF($C18="", "", MAX((O18-P18)*(1+2%)-L18, 0)) -> 1009.3022 | R18: =IF($C18="", "", Q18*(1-VLOOKUP($C18, $U$4:$V$9, 2))) -> 979.02317 | S18: =IF($C18="", "", IF(Q18<=0, 0, MAX(VLOOKUP($D18, $R$4:$S$7, 2)*N18, Q18))) -> 1600 | T18: =IF($C18="", "", IF(AND($C18>1, V17<=0), 0, V17+SUM($E18:$H18)-$J18+K18)) -> 990 | U18: =IF($C18="", "", IF(T18<=0, 0, MAX(VLOOKUP($D18-1, $R$4:$S$7, 2)*$N18-T18, 0)*OFFSET(鑫意锁风险保险费!$B$5, $D18-1, IF($D$3="男", 1, 2))/1000)) -> 0.488 | V18: =IF($C18="", "", MAX((T18-U18)*(1+4%)-$L18, 0)) -> 1029.0925 | W18: =IF($C18="", "", V18*(1-VLOOKUP($C18, $U$4:$V$9, 2))) -> 998.21971 | X18: =IF($C18="", "", IF(V18<=0, 0, MAX(VLOOKUP($D18, $R$4:$S$7, 2)*$N18, V18))) -> 1600
C19: =IF(AND(C18>0, C18<99-$H$3), C18+1,"") -> 2 | D19: =IF(C19="","",D18+1) -> 32 | E19: =IF(C19="", "", IF(C19=1, $F$6, 0)) -> 0 | H19: =IF(C19="", "", IF(AND(C19>=6, D19<=60), OFFSET(利益演示!$G$16, C19-1, 0), IF(D19>60, OFFSET(利益演示!$H$16, C19-1, 0), 0))) -> 0 | I19: =IF(C19="", "", SUM($E$18:H19)) -> 1000 | J19: =IF(C19="","",E19*1%+F19*1%+G19*3%+H19*1%) -> 0 | K19: =IF(C19="", "", ROUND(IF(C19=6, SUM(OFFSET(H18, -4, 0):H18)*1%, IF(C19>6,H18*1%, 0)),0)) -> 0 | M19: =IF(C19="", "", L19*VLOOKUP(C19, $U$4:$V$9, 2)) -> 0 | N19: =IF(C19="", "", MAX(I19-SUM(L$17:L18), 0)) -> 1000 | O19: =IF($C19="", "", IF(AND($C19>1, Q18<=0), 0, Q18+SUM($E19:$H19)-$J19+K19)) -> 1009.3022 | P19: =IF($C19="", "", IF(O19<=0, 0, MAX(VLOOKUP($D19-1, $R$4:$S$7, 2)*$N19-O19, 0)*OFFSET(鑫意锁风险保险费!$B$5, $D19-1, IF($D$3="男", 1, 2))/1000)) -> 0.5020931 | Q19: =IF($C19="", "", MAX((O19-P19)*(1+2%)-L19, 0)) -> 1028.9761 | R19: =IF($C19="", "", Q19*(1-VLOOKUP($C19, $U$4:$V$9, 2))) -> 1018.6864 | S19: =IF($C19="", "", IF(Q19<=0, 0, MAX(VLOOKUP($D19, $R$4:$S$7, 2)*N19, Q19))) -> 1600 | T19: =IF($C19="", "", IF(AND($C19>1, V18<=0), 0, V18+SUM($E19:$H19)-$J19+K19)) -> 1029.0925 | U19: =IF($C19="", "", IF(T19<=0, 0, MAX(VLOOKUP($D19-1, $R$4:$S$7, 2)*$N19-T19, 0)*OFFSET(鑫意锁风险保险费!$B$5, $D19-1, IF($D$3="男", 1, 2))/1000)) -> 0.48527139 | V19: =IF($C19="", "", MAX((T19-U19)*(1+4%)-$L19, 0)) -> 1069.7515 | W19: =IF($C19="", "", V19*(1-VLOOKUP($C19, $U$4:$V$9, 2))) -> 1059.054 | X19: =IF($C19="", "", IF(V19<=0, 0, MAX(VLOOKUP($D19, $R$4:$S$7, 2)*$N19, V19))) -> 1600
C20: =IF(AND(C19>0, C19<99-$H$3), C19+1,"") -> 3 | D20: =IF(C20="","",D19+1) -> 33 | E20: =IF(C20="", "", IF(C20=1, $F$6, 0)) -> 0 | H20: =IF(C20="", "", IF(AND(C20>=6, D20<=60), OFFSET(利益演示!$G$16, C20-1, 0), IF(D20>60, OFFSET(利益演示!$H$16, C20-1, 0), 0))) -> 0 | I20: =IF(C20="", "", SUM($E$18:H20)) -> 1000 | J20: =IF(C20="","",E20*1%+F20*1%+G20*3%+H20*1%) -> 0 | K20: =IF(C20="", "", ROUND(IF(C20=6, SUM(OFFSET(H19, -4, 0):H19)*1%, IF(C20>6,H19*1%, 0)),0)) -> 0 | M20: =IF(C20="", "", L20*VLOOKUP(C20, $U$4:$V$9, 2)) -> 0 | N20: =IF(C20="", "", MAX(I20-SUM(L$17:L19), 0)) -> 1000 | O20: =IF($C20="", "", IF(AND($C20>1, Q19<=0), 0, Q19+SUM($E20:$H20)-$J20+K20)) -> 1028.9761 | P20: =IF($C20="", "", IF(O20<=0, 0, MAX(VLOOKUP($D20-1, $R$4:$S$7, 2)*$N20-O20, 0)*OFFSET(鑫意锁风险保险费!$B$5, $D20-1, IF($D$3="男", 1, 2))/1000)) -> 0.51392147 | Q20: =IF($C20="", "", MAX((O20-P20)*(1+2%)-L20, 0)) -> 1049.0315 | R20: =IF($C20="", "", Q20*(1-VLOOKUP($C20, $U$4:$V$9, 2))) -> 1038.5412 | S20: =IF($C20="", "", IF(Q20<=0, 0, MAX(VLOOKUP($D20, $R$4:$S$7, 2)*N20, Q20))) -> 1600 | T20: =IF($C20="", "", IF(AND($C20>1, V19<=0), 0, V19+SUM($E20:$H20)-$J20+K20)) -> 1069.7515 | U20: =IF($C20="", "", IF(T20<=0, 0, MAX(VLOOKUP($D20-1, $R$4:$S$7, 2)*$N20-T20, 0)*OFFSET(鑫意锁风险保险费!$B$5, $D20-1, IF($D$3="男", 1, 2))/1000)) -> 0.47722365 | V20: =IF($C20="", "", MAX((T20-U20)*(1+4%)-$L20, 0)) -> 1112.0452 | W20: =IF($C20="", "", V20*(1-VLOOKUP($C20, $U$4:$V$9, 2))) -> 1100.9248 | X20: =IF($C20="", "", IF(V20<=0, 0, MAX(VLOOKUP($D20, $R$4:$S$7, 2)*$N20, V20))) -> 1600
C21: =IF(AND(C20>0, C20<99-$H$3), C20+1,"") -> 4 | D21: =IF(C21="","",D20+1) -> 34 | E21: =IF(C21="", "", IF(C21=1, $F$6, 0)) -> 0 | F21: 100000 | H21: =IF(C21="", "", IF(AND(C21>=6, D21<=60), OFFSET(利益演示!$G$16, C21-1, 0), IF(D21>60, OFFSET(利益演示!$H$16, C21-1, 0), 0))) -> 0 | I21: =IF(C21="", "", SUM($E$18:H21)) -> 101000 | J21: =IF(C21="","",E21*1%+F21*1%+G21*3%+H21*1%) -> 1000 | K21: =IF(C21="", "", ROUND(IF(C21=6, SUM(OFFSET(H20, -4, 0):H20)*1%, IF(C21>6,H20*1%, 0)),0)) -> 0 | M21: =IF(C21="", "", L21*VLOOKUP(C21, $U$4:$V$9, 2)) -> 0 | N21: =IF(C21="", "", MAX(I21-SUM(L$17:L20), 0)) -> 101000 | O21: =IF($C21="", "", IF(AND($C21>1, Q20<=0), 0, Q20+SUM($E21:$H21)-$J21+K21)) -> 100049.03 | P21: =IF($C21="", "", IF(O21<=0, 0, MAX(VLOOKUP($D21-1, $R$4:$S$7, 2)*$N21-O21, 0)*OFFSET(鑫意锁风险保险费!$B$5, $D21-1, IF($D$3="男", 1, 2))/1000)) -> 59.704439 | Q21: =IF($C21="", "", MAX((O21-P21)*(1+2%)-L21, 0)) -> 101989.11 | R21: =IF($C21="", "", Q21*(1-VLOOKUP($C21, $U$4:$V$9, 2))) -> 100969.22 | S21: =IF($C21="", "", IF(Q21<=0, 0, MAX(VLOOKUP($D21, $R$4:$S$7, 2)*N21, Q21))) -> 161600 | T21: =IF($C21="", "", IF(AND($C21>1, V20<=0), 0, V20+SUM($E21:$H21)-$J21+K21)) -> 100112.05 | U21: =IF($C21="", "", IF(T21<=0, 0, MAX(VLOOKUP($D21-1, $R$4:$S$7, 2)*$N21-T21, 0)*OFFSET(鑫意锁风险保险费!$B$5, $D21-1, IF($D$3="男", 1, 2))/1000)) -> 59.643316 | V21: =IF($C21="", "", MAX((T21-U21)*(1+4%)-$L21, 0)) -> 104054.5 | W21: =IF($C21="", "", V21*(1-VLOOKUP($C21, $U$4:$V$9, 2))) -> 103013.95 | X21: =IF($C21="", "", IF(V21<=0, 0, MAX(VLOOKUP($D21, $R$4:$S$7, 2)*$N21, V21))) -> 161600
C22: =IF(AND(C21>0, C21<99-$H$3), C21+1,"") -> 5 | D22: =IF(C22="","",D21+1) -> 35 | E22: =IF(C22="", "", IF(C22=1, $F$6, 0)) -> 0 | F22: 100000 | G22: 100000 | H22: =IF(C22="", "", IF(AND(C22>=6, D22<=60), OFFSET(利益演示!$G$16, C22-1, 0), IF(D22>60, OFFSET(利益演示!$H$16, C22-1, 0), 0))) -> 0 | I22: =IF(C22="", "", SUM($E$18:H22)) -> 301000 | J22: =IF(C22="","",E22*1%+F22*1%+G22*3%+H22*1%) -> 4000 | K22: =IF(C22="", "", ROUND(IF(C22=6, SUM(OFFSET(H21, -4, 0):H21)*1%, IF(C22>6,H21*1%, 0)),0)) -> 0 | M22: =IF(C22="", "", L22*VLOOKUP(C22, $U$4:$V$9, 2)) -> 0 | N22: =IF(C22="", "", MAX(I22-SUM(L$17:L21), 0)) -> 301000 | O22: =IF($C22="", "", IF(AND($C22>1, Q21<=0), 0, Q21+SUM($E22:$H22)-$J22+K22)) -> 297989.11 | P22: =IF($C22="", "", IF(O22<=0, 0, MAX(VLOOKUP($D22-1, $R$4:$S$7, 2)*$N22-O22, 0)*OFFSET(鑫意锁风险保险费!$B$5, $D22-1, IF($D$3="男", 1, 2))/1000)) -> 190.95532 | Q22: =IF($C22="", "", MAX((O22-P22)*(1+2%)-L22, 0)) -> 303754.12 | R22: =IF($C22="", "", Q22*(1-VLOOKUP($C22, $U$4:$V$9, 2))) -> 300716.58 | S22: =IF($C22="", "", IF(Q22<=0, 0, MAX(VLOOKUP($D22, $R$4:$S$7, 2)*N22, Q22))) -> 481600 | T22: =IF($C22="", "", IF(AND($C22>1, V21<=0), 0, V21+SUM($E22:$H22)-$J22+K22)) -> 300054.5 | U22: =IF($C22="", "", IF(T22<=0, 0, MAX(VLOOKUP($D22-1, $R$4:$S$7, 2)*$N22-T22, 0)*OFFSET(鑫意锁风险保险费!$B$5, $D22-1, IF($D$3="男", 1, 2))/1000)) -> 188.80732 | V22: =IF($C22="", "", MAX((T22-U22)*(1+4%)-$L22, 0)) -> 311860.32 | W22: =IF($C22="", "", V22*(1-VLOOKUP($C22, $U$4:$V$9, 2))) -> 308741.72 | X22: =IF($C22="", "", IF(V22<=0, 0, MAX(VLOOKUP($D22, $R$4:$S$7, 2)*$N22, V22))) -> 481600
C23: =IF(AND(C22>0, C22<99-$H$3), C22+1,"") -> 6 | D23: =IF(C23="","",D22+1) -> 36 | E23: =IF(C23="", "", IF(C23=1, $F$6, 0)) -> 0 | F23: 100000 | H23: =IF(C23="", "", IF(AND(C23>=6, D23<=60), OFFSET(利益演示!$G$16, C23-1, 0), IF(D23>60, OFFSET(利益演示!$H$16, C23-1, 0), 0))) -> 24300 | I23: =IF(C23="", "", SUM($E$18:H23)) -> 425300 | J23: =IF(C23="","",E23*1%+F23*1%+G23*3%+H23*1%) -> 1243 | K23: =IF(C23="", "", ROUND(IF(C23=6, SUM(OFFSET(H22, -4, 0):H22)*1%, IF(C23>6,H22*1%, 0)),0)) -> 0 | M23: =IF(C23="", "", L23*VLOOKUP(C23, $U$4:$V$9, 2)) -> 0 | N23: =IF(C23="", "", MAX(I23-SUM(L$17:L22), 0)) -> 425300 | O23: =IF($C23="", "", IF(AND($C23>1, Q22<=0), 0, Q22+SUM($E23:$H23)-$J23+K23)) -> 426811.12 | P23: =IF($C23="", "", IF(O23<=0, 0, MAX(VLOOKUP($D23-1, $R$4:$S$7, 2)*$N23-O23, 0)*OFFSET(鑫意锁风险保险费!$B$5, $D23-1, IF($D$3="男", 1, 2))/1000)) -> 281.57246 | Q23: =IF($C23="", "", MAX((O23-P23)*(1+2%)-L23, 0)) -> 435060.14 | R23: =IF($C23="", "", Q23*(1-VLOOKUP($C23, $U$4:$V$9, 2))) -> 435060.14 | S23: =IF($C23="", "", IF(Q23<=0, 0, MAX(VLOOKUP($D23, $R$4:$S$7, 2)*N23, Q23))) -> 680480 | T23: =IF($C23="", "", IF(AND($C23>1, V22<=0), 0, V22+SUM($E23:$H23)-$J23+K23)) -> 434917.32 | U23: =IF($C23="", "", IF(T23<=0, 0, MAX(VLOOKUP($D23-1, $R$4:$S$7, 2)*$N23-T23, 0)*OFFSET(鑫意锁风险保险费!$B$5, $D23-1, IF($D$3="男", 1, 2))/1000)) -> 272.57458 | V23: =IF($C23="", "", MAX((T23-U23)*(1+4%)-$L23, 0)) -> 452030.53 | W23: =IF($C23="", "", V23*(1-VLOOKUP($C23, $U$4:$V$9, 2))) -> 452030.53 | X23: =IF($C23="", "", IF(V23<=0, 0, MAX(VLOOKUP($D23, $R$4:$S$7, 2)*$N23, V23))) -> 680480
C24: =IF(AND(C23>0, C23<99-$H$3), C23+1,"") -> 7 | D24: =IF(C24="","",D23+1) -> 37 | E24: =IF(C24="", "", IF(C24=1, $F$6, 0)) -> 0 | F24: 100000 | H24: =IF(C24="", "", IF(AND(C24>=6, D24<=60), OFFSET(利益演示!$G$16, C24-1, 0), IF(D24>60, OFFSET(利益演示!$H$16, C24-1, 0), 0))) -> 24300 | I24: =IF(C24="", "", SUM($E$18:H24)) -> 549600 | J24: =IF(C24="","",E24*1%+F24*1%+G24*3%+H24*1%) -> 1243 | K24: =IF(C24="", "", ROUND(IF(C24=6, SUM(OFFSET(H23, -4, 0):H23)*1%, IF(C24>6,H23*1%, 0)),0)) -> 243 | M24: =IF(C24="", "", L24*VLOOKUP(C24, $U$4:$V$9, 2)) -> 0 | N24: =IF(C24="", "", MAX(I24-SUM(L$17:L23), 0)) -> 549600 | O24: =IF($C24="", "", IF(AND($C24>1, Q23<=0), 0, Q23+SUM($E24:$H24)-$J24+K24)) -> 558360.14 | P24: =IF($C24="", "", IF(O24<=0, 0, MAX(VLOOKUP($D24-1, $R$4:$S$7, 2)*$N24-O24, 0)*OFFSET(鑫意锁风险保险费!$B$5, $D24-1, IF($D$3="男", 1, 2))/1000)) -> 385.19983 | Q24: =IF($C24="", "", MAX((O24-P24)*(1+2%)-L24, 0)) -> 569134.44 | R24: =IF($C24="", "", Q24*(1-VLOOKUP($C24, $U$4:$V$9, 2))) -> 569134.44 | S24: =IF($C24="", "", IF(Q24<=0, 0, MAX(VLOOKUP($D24, $R$4:$S$7, 2)*N24, Q24))) -> 879360 | T24: =IF($C24="", "", IF(AND($C24>1, V23<=0), 0, V23+SUM($E24:$H24)-$J24+K24)) -> 575330.53 | U24: =IF($C24="", "", IF(T24<=0, 0, MAX(VLOOKUP($D24-1, $R$4:$S$7, 2)*$N24-T24, 0)*OFFSET(鑫意锁风险保险费!$B$5, $D24-1, IF($D$3="男", 1, 2))/1000)) -> 364.83536 | V24: =IF($C24="", "", MAX((T24-U24)*(1+4%)-$L24, 0)) -> 597964.33 | W24: =IF($C24="", "", V24*(1-VLOOKUP($C24, $U$4:$V$9, 2))) -> 597964.33 | X24: =IF($C24="", "", IF(V24<=0, 0, MAX(VLOOKUP($D24, $R$4:$S$7, 2)*$N24, V24))) -> 879360
C25: =IF(AND(C24>0, C24<99-$H$3), C24+1,"") -> 8 | D25: =IF(C25="","",D24+1) -> 38 | E25: =IF(C25="", "", IF(C25=1, $F$6, 0)) -> 0 | H25: =IF(C25="", "", IF(AND(C25>=6, D25<=60), OFFSET(利益演示!$G$16, C25-1, 0), IF(D25>60, OFFSET(利益演示!$H$16, C25-1, 0), 0))) -> 24300 | I25: =IF(C25="", "", SUM($E$18:H25)) -> 573900 | J25: =IF(C25="","",E25*1%+F25*1%+G25*3%+H25*1%) -> 243 | K25: =IF(C25="", "", ROUND(IF(C25=6, SUM(OFFSET(H24, -4, 0):H24)*1%, IF(C25>6,H24*1%, 0)),0)) -> 243 | M25: =IF(C25="", "", L25*VLOOKUP(C25, $U$4:$V$9, 2)) -> 0 | N25: =IF(C25="", "", MAX(I25-SUM(L$17:L24), 0)) -> 573900 | O25: =IF($C25="", "", IF(AND($C25>1, Q24<=0), 0, Q24+SUM($E25:$H25)-$J25+K25)) -> 593434.44 | P25: =IF($C25="", "", IF(O25<=0, 0, MAX(VLOOKUP($D25-1, $R$4:$S$7, 2)*$N25-O25, 0)*OFFSET(鑫意锁风险保险费!$B$5, $D25-1, IF($D$3="男", 1, 2))/1000)) -> 418.99917 | Q25: =IF($C25="", "", MAX((O25-P25)*(1+2%)-L25, 0)) -> 604875.75 | R25: =IF($C25="", "", Q25*(1-VLOOKUP($C25, $U$4:$V$9, 2))) -> 604875.75 | S25: =IF($C25="", "", IF(Q25<=0, 0, MAX(VLOOKUP($D25, $R$4:$S$7, 2)*N25, Q25))) -> 918240 | T25: =IF($C25="", "", IF(AND($C25>1, V24<=0), 0, V24+SUM($E25:$H25)-$J25+K25)) -> 622264.33 | U25: =IF($C25="", "", IF(T25<=0, 0, MAX(VLOOKUP($D25-1, $R$4:$S$7, 2)*$N25-T25, 0)*OFFSET(鑫意锁风险保险费!$B$5, $D25-1, IF($D$3="男", 1, 2))/1000)) -> 381.80862 | V25: =IF($C25="", "", MAX((T25-U25)*(1+4%)-$L25, 0)) -> 646757.82 | W25: =IF($C25="", "", V25*(1-VLOOKUP($C25, $U$4:$V$9, 2))) -> 646757.82 | X25: =IF($C25="", "", IF(V25<=0, 0, MAX(VLOOKUP($D25, $R$4:$S$7, 2)*$N25, V25))) -> 918240
C26: =IF(AND(C25>0, C25<99-$H$3), C25+1,"") -> 9 | D26: =IF(C26="","",D25+1) -> 39 | E26: =IF(C26="", "", IF(C26=1, $F$6, 0)) -> 0 | H26: =IF(C26="", "", IF(AND(C26>=6, D26<=60), OFFSET(利益演示!$G$16, C26-1, 0), IF(D26>60, OFFSET(利益演示!$H$16, C26-1, 0), 0))) -> 24300 | I26: =IF(C26="", "", SUM($E$18:H26)) -> 598200 | J26: =IF(C26="","",E26*1%+F26*1%+G26*3%+H26*1%) -> 243 | K26: =IF(C26="", "", ROUND(IF(C26=6, SUM(OFFSET(H25, -4, 0):H25)*1%, IF(C26>6,H25*1%, 0)),0)) -> 243 | M26: =IF(C26="", "", L26*VLOOKUP(C26, $U$4:$V$9, 2)) -> 0 | N26: =IF(C26="", "", MAX(I26-SUM(L$17:L25), 0)) -> 598200 | O26: =IF($C26="", "", IF(AND($C26>1, Q25<=0), 0, Q25+SUM($E26:$H26)-$J26+K26)) -> 629175.75 | P26: =IF($C26="", "", IF(O26<=0, 0, MAX(VLOOKUP($D26-1, $R$4:$S$7, 2)*$N26-O26, 0)*OFFSET(鑫意锁风险保险费!$B$5, $D26-1, IF($D$3="男", 1, 2))/1000)) -> 459.12195 | Q26: =IF($C26="", "", MAX((O26-P26)*(1+2%)-L26, 0)) -> 641290.96 | R26: =IF($C26="", "", Q26*(1-VLOOKUP($C26, $U$4:$V$9, 2))) -> 641290.96 | S26: =IF($C26="", "", IF(Q26<=0, 0, MAX(VLOOKUP($D26, $R$4:$S$7, 2)*N26, Q26))) -> 957120 | T26: =IF($C26="", "", IF(AND($C26>1, V25<=0), 0, V25+SUM($E26:$H26)-$J26+K26)) -> 671057.82 | U26: =IF($C26="", "", IF(T26<=0, 0, MAX(VLOOKUP($D26-1, $R$4:$S$7, 2)*$N26-T26, 0)*OFFSET(鑫意锁风险保险费!$B$5, $D26-1, IF($D$3="男", 1, 2))/1000)) -> 400.48705 | V26: =IF($C26="", "", MAX((T26-U26)*(1+4%)-$L26, 0)) -> 697483.62 | W26: =IF($C26="", "", V26*(1-VLOOKUP($C26, $U$4:$V$9, 2))) -> 697483.62 | X26: =IF($C26="", "", IF(V26<=0, 0, MAX(VLOOKUP($D26, $R$4:$S$7, 2)*$N26, V26))) -> 957120
C27: =IF(AND(C26>0, C26<99-$H$3), C26+1,"") -> 10 | D27: =IF(C27="","",D26+1) -> 40 | E27: =IF(C27="", "", IF(C27=1, $F$6, 0)) -> 0 | H27: =IF(C27="", "", IF(AND(C27>=6, D27<=60), OFFSET(利益演示!$G$16, C27-1, 0), IF(D27>60, OFFSET(利益演示!$H$16, C27-1, 0), 0))) -> 24300 | I27: =IF(C27="", "", SUM($E$18:H27)) -> 622500 | J27: =IF(C27="","",E27*1%+F27*1%+G27*3%+H27*1%) -> 243 | K27: =IF(C27="", "", ROUND(IF(C27=6, SUM(OFFSET(H26, -4, 0):H26)*1%, IF(C27>6,H26*1%, 0)),0)) -> 243 | M27: =IF(C27="", "", L27*VLOOKUP(C27, $U$4:$V$9, 2)) -> 0 | N27: =IF(C27="", "", MAX(I27-SUM(L$17:L26), 0)) -> 622500 | O27: =IF($C27="", "", IF(AND($C27>1, Q26<=0), 0, Q26+SUM($E27:$H27)-$J27+K27)) -> 665590.96 | P27: =IF($C27="", "", IF(O27<=0, 0, MAX(VLOOKUP($D27-1, $R$4:$S$7, 2)*$N27-O27, 0)*OFFSET(鑫意锁风险保险费!$B$5, $D27-1, IF($D$3="男", 1, 2))/1000)) -> 502.22174 | Q27: =IF($C27="", "", MAX((O27-P27)*(1+2%)-L27, 0)) -> 678390.51 | R27: =IF($C27="", "", Q27*(1-VLOOKUP($C27, $U$4:$V$9, 2))) -> 678390.51 | S27: =IF($C27="", "", IF(Q27<=0, 0, MAX(VLOOKUP($D27, $R$4:$S$7, 2)*N27, Q27))) -> 996000 | T27: =IF($C27="", "", IF(AND($C27>1, V26<=0), 0, V26+SUM($E27:$H27)-$J27+K27)) -> 721783.62 | U27: =IF($C27="", "", IF(T27<=0, 0, MAX(VLOOKUP($D27-1, $R$4:$S$7, 2)*$N27-T27, 0)*OFFSET(鑫意锁风险保险费!$B$5, $D27-1, IF($D$3="男", 1, 2))/1000)) -> 416.80889 | V27: =IF($C27="", "", MAX((T27-U27)*(1+4%)-$L27, 0)) -> 750221.49 | W27: =IF($C27="", "", V27*(1-VLOOKUP($C27, $U$4:$V$9, 2))) -> 750221.49 | X27: =IF($C27="", "", IF(V27<=0, 0, MAX(VLOOKUP($D27, $R$4:$S$7, 2)*$N27, V27))) -> 996000
C28: =IF(AND(C27>0, C27<99-$H$3), C27+1,"") -> 11 | D28: =IF(C28="","",D27+1) -> 41 | E28: =IF(C28="", "", IF(C28=1, $F$6, 0)) -> 0 | H28: =IF(C28="", "", IF(AND(C28>=6, D28<=60), OFFSET(利益演示!$G$16, C28-1, 0), IF(D28>60, OFFSET(利益演示!$H$16, C28-1, 0), 0))) -> 24300 | I28: =IF(C28="", "", SUM($E$18:H28)) -> 646800 | J28: =IF(C28="","",E28*1%+F28*1%+G28*3%+H28*1%) -> 243 | K28: =IF(C28="", "", ROUND(IF(C28=6, SUM(OFFSET(H27, -4, 0):H27)*1%, IF(C28>6,H27*1%, 0)),0)) -> 243 | M28: =IF(C28="", "", L28*VLOOKUP(C28, $U$4:$V$9, 2)) -> 0 | N28: =IF(C28="", "", MAX(I28-SUM(L$17:L27), 0)) -> 646800 | O28: =IF($C28="", "", IF(AND($C28>1, Q27<=0), 0, Q27+SUM($E28:$H28)-$J28+K28)) -> 702690.51 | P28: =IF($C28="", "", IF(O28<=0, 0, MAX(VLOOKUP($D28-1, $R$4:$S$7, 2)*$N28-O28, 0)*OFFSET(鑫意锁风险保险费!$B$5, $D28-1, IF($D$3="男", 1, 2))/1000)) -> 548.11266 | Q28: =IF($C28="", "", MAX((O28-P28)*(1+2%)-L28, 0)) -> 716185.25 | R28: =IF($C28="", "", Q28*(1-VLOOKUP($C28, $U$4:$V$9, 2))) -> 716185.25 | S28: =IF($C28="", "", IF(Q28<=0, 0, MAX(VLOOKUP($D28, $R$4:$S$7, 2)*N28, Q28))) -> 1034880 | T28: =IF($C28="", "", IF(AND($C28>1, V27<=0), 0, V27+SUM($E28:$H28)-$J28+K28)) -> 774521.49 | U28: =IF($C28="", "", IF(T28<=0, 0, MAX(VLOOKUP($D28-1, $R$4:$S$7, 2)*$N28-T28, 0)*OFFSET(鑫意锁风险保险费!$B$5, $D28-1, IF($D$3="男", 1, 2))/1000)) -> 429.59154 | V28: =IF($C28="", "", MAX((T28-U28)*(1+4%)-$L28, 0)) -> 805055.57 | W28: =IF($C28="", "", V28*(1-VLOOKUP($C28, $U$4:$V$9, 2))) -> 805055.57 | X28: =IF($C28="", "", IF(V28<=0, 0, MAX(VLOOKUP($D28, $R$4:$S$7, 2)*$N28, V28))) -> 1034880
C29: =IF(AND(C28>0, C28<99-$H$3), C28+1,"") -> 12 | D29: =IF(C29="","",D28+1) -> 42 | E29: =IF(C29="", "", IF(C29=1, $F$6, 0)) -> 0 | H29: =IF(C29="", "", IF(AND(C29>=6, D29<=60), OFFSET(利益演示!$G$16, C29-1, 0), IF(D29>60, OFFSET(利益演示!$H$16, C29-1, 0), 0))) -> 24300 | I29: =IF(C29="", "", SUM($E$18:H29)) -> 671100 | J29: =IF(C29="","",E29*1%+F29*1%+G29*3%+H29*1%) -> 243 | K29: =IF(C29="", "", ROUND(IF(C29=6, SUM(OFFSET(H28, -4, 0):H28)*1%, IF(C29>6,H28*1%, 0)),0)) -> 243 | M29: =IF(C29="", "", L29*VLOOKUP(C29, $U$4:$V$9, 2)) -> 0 | N29: =IF(C29="", "", MAX(I29-SUM(L$17:L28), 0)) -> 671100 | O29: =IF($C29="", "", IF(AND($C29>1, Q28<=0), 0, Q28+SUM($E29:$H29)-$J29+K29)) -> 740485.25 | P29: =IF($C29="", "", IF(O29<=0, 0, MAX(VLOOKUP($D29-1, $R$4:$S$7, 2)*$N29-O29, 0)*OFFSET(鑫意锁风险保险费!$B$5, $D29-1, IF($D$3="男", 1, 2))/1000)) -> 599.89455 | Q29: =IF($C29="", "", MAX((O29-P29)*(1+2%)-L29, 0)) -> 754683.06 | R29: =IF($C29="", "", Q29*(1-VLOOKUP($C29, $U$4:$V$9, 2))) -> 754683.06 | S29: =IF($C29="", "", IF(Q29<=0, 0, MAX(VLOOKUP($D29, $R$4:$S$7, 2)*N29, Q29))) -> 939540 | T29: =IF($C29="", "", IF(AND($C29>1, V28<=0), 0, V28+SUM($E29:$H29)-$J29+K29)) -> 829355.57 | U29: =IF($C29="", "", IF(T29<=0, 0, MAX(VLOOKUP($D29-1, $R$4:$S$7, 2)*$N29-T29, 0)*OFFSET(鑫意锁风险保险费!$B$5, $D29-1, IF($D$3="男", 1, 2))/1000)) -> 439.92797 | V29: =IF($C29="", "", MAX((T29-U29)*(1+4%)-$L29, 0)) -> 862072.27 | W29: =IF($C29="", "", V29*(1-VLOOKUP($C29, $U$4:$V$9, 2))) -> 862072.27 | X29: =IF($C29="", "", IF(V29<=0, 0, MAX(VLOOKUP($D29, $R$4:$S$7, 2)*$N29, V29))) -> 939540
C30: =IF(AND(C29>0, C29<99-$H$3), C29+1,"") -> 13 | D30: =IF(C30="","",D29+1) -> 43 | E30: =IF(C30="", "", IF(C30=1, $F$6, 0)) -> 0 | H30: =IF(C30="", "", IF(AND(C30>=6, D30<=60), OFFSET(利益演示!$G$16, C30-1, 0), IF(D30>60, OFFSET(利益演示!$H$16, C30-1, 0), 0))) -> 24300 | I30: =IF(C30="", "", SUM($E$18:H30)) -> 695400 | J30: =IF(C30="","",E30*1%+F30*1%+G30*3%+H30*1%) -> 243 | K30: =IF(C30="", "", ROUND(IF(C30=6, SUM(OFFSET(H29, -4, 0):H29)*1%, IF(C30>6,H29*1%, 0)),0)) -> 243 | M30: =IF(C30="", "", L30*VLOOKUP(C30, $U$4:$V$9, 2)) -> 0 | N30: =IF(C30="", "", MAX(I30-SUM(L$17:L29), 0)) -> 695400 | O30: =IF($C30="", "", IF(AND($C30>1, Q29<=0), 0, Q29+SUM($E30:$H30)-$J30+K30)) -> 778983.06 | P30: =IF($C30="", "", IF(O30<=0, 0, MAX(VLOOKUP($D30-1, $R$4:$S$7, 2)*$N30-O30, 0)*OFFSET(鑫意锁风险保险费!$B$5, $D30-1, IF($D$3="男", 1, 2))/1000)) -> 385.26234 | Q30: =IF($C30="", "", MAX((O30-P30)*(1+2%)-L30, 0)) -> 794169.75 | R30: =IF($C30="", "", Q30*(1-VLOOKUP($C30, $U$4:$V$9, 2))) -> 794169.75 | S30: =IF($C30="", "", IF(Q30<=0, 0, MAX(VLOOKUP($D30, $R$4:$S$7, 2)*N30, Q30))) -> 973560 | T30: =IF($C30="", "", IF(AND($C30>1, V29<=0), 0, V29+SUM($E30:$H30)-$J30+K30)) -> 886372.27 | U30: =IF($C30="", "", IF(T30<=0, 0, MAX(VLOOKUP($D30-1, $R$4:$S$7, 2)*$N30-T30, 0)*OFFSET(鑫意锁风险保险费!$B$5, $D30-1, IF($D$3="男", 1, 2))/1000)) -> 172.63171 | V30: =IF($C30="", "", MAX((T30-U30)*(1+4%)-$L30, 0)) -> 921647.62 | W30: =IF($C30="", "", V30*(1-VLOOKUP($C30, $U$4:$V$9, 2))) -> 921647.62 | X30: =IF($C30="", "", IF(V30<=0, 0, MAX(VLOOKUP($D30, $R$4:$S$7, 2)*$N30, V30))) -> 973560
C31: =IF(AND(C30>0, C30<99-$H$3), C30+1,"") -> 14 | D31: =IF(C31="","",D30+1) -> 44 | E31: =IF(C31="", "", IF(C31=1, $F$6, 0)) -> 0 | H31: =IF(C31="", "", IF(AND(C31>=6, D31<=60), OFFSET(利益演示!$G$16, C31-1, 0), IF(D31>60, OFFSET(利益演示!$H$16, C31-1, 0), 0))) -> 24300 | I31: =IF(C31="", "", SUM($E$18:H31)) -> 719700 | J31: =IF(C31="","",E31*1%+F31*1%+G31*3%+H31*1%) -> 243 | K31: =IF(C31="", "", ROUND(IF(C31=6, SUM(OFFSET(H30, -4, 0):H30)*1%, IF(C31>6,H30*1%, 0)),0)) -> 243 | M31: =IF(C31="", "", L31*VLOOKUP(C31, $U$4:$V$9, 2)) -> 0 | N31: =IF(C31="", "", MAX(I31-SUM(L$17:L30), 0)) -> 719700 | O31: =IF($C31="", "", IF(AND($C31>1, Q30<=0), 0, Q30+SUM($E31:$H31)-$J31+K31)) -> 818469.75 | P31: =IF($C31="", "", IF(O31<=0, 0, MAX(VLOOKUP($D31-1, $R$4:$S$7, 2)*$N31-O31, 0)*OFFSET(鑫意锁风险保险费!$B$5, $D31-1, IF($D$3="男", 1, 2))/1000)) -> 410.36923 | Q31: =IF($C31="", "", MAX((O31-P31)*(1+2%)-L31, 0)) -> 834420.57 | R31: =IF($C31="", "", Q31*(1-VLOOKUP($C31, $U$4:$V$9, 2))) -> 834420.57 | S31: =IF($C31="", "", IF(Q31<=0, 0, MAX(VLOOKUP($D31, $R$4:$S$7, 2)*N31, Q31))) -> 1007580 | T31: =IF($C31="", "", IF(AND($C31>1, V30<=0), 0, V30+SUM($E31:$H31)-$J31+K31)) -> 945947.62 | U31: =IF($C31="", "", IF(T31<=0, 0, MAX(VLOOKUP($D31-1, $R$4:$S$7, 2)*$N31-T31, 0)*OFFSET(鑫意锁风险保险费!$B$5, $D31-1, IF($D$3="男", 1, 2))/1000)) -> 133.74226 | V31: =IF($C31="", "", MAX((T31-U31)*(1+4%)-$L31, 0)) -> 983646.44 | W31: =IF($C31="", "", V31*(1-VLOOKUP($C31, $U$4:$V$9, 2))) -> 983646.44 | X31: =IF($C31="", "", IF(V31<=0, 0, MAX(VLOOKUP($D31, $R$4:$S$7, 2)*$N31, V31))) -> 1007580
C32: =IF(AND(C31>0, C31<99-$H$3), C31+1,"") -> 15 | D32: =IF(C32="","",D31+1) -> 45 | E32: =IF(C32="", "", IF(C32=1, $F$6, 0)) -> 0 | H32: =IF(C32="", "", IF(AND(C32>=6, D32<=60), OFFSET(利益演示!$G$16, C32-1, 0), IF(D32>60, OFFSET(利益演示!$H$16, C32-1, 0), 0))) -> 24300 | I32: =IF(C32="", "", SUM($E$18:H32)) -> 744000 | J32: =IF(C32="","",E32*1%+F32*1%+G32*3%+H32*1%) -> 243 | K32: =IF(C32="", "", ROUND(IF(C32=6, SUM(OFFSET(H31, -4, 0):H31)*1%, IF(C32>6,H31*1%, 0)),0)) -> 243 | M32: =IF(C32="", "", L32*VLOOKUP(C32, $U$4:$V$9, 2)) -> 0 | N32: =IF(C32="", "", MAX(I32-SUM(L$17:L31), 0)) -> 744000 | O32: =IF($C32="", "", IF(AND($C32>1, Q31<=0), 0, Q31+SUM($E32:$H32)-$J32+K32)) -> 858720.57 | P32: =IF($C32="", "", IF(O32<=0, 0, MAX(VLOOKUP($D32-1, $R$4:$S$7, 2)*$N32-O32, 0)*OFFSET(鑫意锁风险保险费!$B$5, $D32-1, IF($D$3="男", 1, 2))/1000)) -> 437.08183 | Q32: =IF($C32="", "", MAX((O32-P32)*(1+2%)-L32, 0)) -> 875449.16 | R32: =IF($C32="", "", Q32*(1-VLOOKUP($C32, $U$4:$V$9, 2))) -> 875449.16 | S32: =IF($C32="", "", IF(Q32<=0, 0, MAX(VLOOKUP($D32, $R$4:$S$7, 2)*N32, Q32))) -> 1041600 | T32: =IF($C32="", "", IF(AND($C32>1, V31<=0), 0, V31+SUM($E32:$H32)-$J32+K32)) -> 1007946.4 | U32: =IF($C32="", "", IF(T32<=0, 0, MAX(VLOOKUP($D32-1, $R$4:$S$7, 2)*$N32-T32, 0)*OFFSET(鑫意锁风险保险费!$B$5, $D32-1, IF($D$3="男", 1, 2))/1000)) -> 80.432016 | V32: =IF($C32="", "", MAX((T32-U32)*(1+4%)-$L32, 0)) -> 1048180.6 | W32: =IF($C32="", "", V32*(1-VLOOKUP($C32, $U$4:$V$9, 2))) -> 1048180.6 | X32: =IF($C32="", "", IF(V32<=0, 0, MAX(VLOOKUP($D32, $R$4:$S$7, 2)*$N32, V32))) -> 1048180.6
C33: =IF(AND(C32>0, C32<99-$H$3), C32+1,"") -> 16 | D33: =IF(C33="","",D32+1) -> 46 | E33: =IF(C33="", "", IF(C33=1, $F$6, 0)) -> 0 | H33: =IF(C33="", "", IF(AND(C33>=6, D33<=60), OFFSET(利益演示!$G$16, C33-1, 0), IF(D33>60, OFFSET(利益演示!$H$16, C33-1, 0), 0))) -> 24300 | I33: =IF(C33="", "", SUM($E$18:H33)) -> 768300 | J33: =IF(C33="","",E33*1%+F33*1%+G33*3%+H33*1%) -> 243 | K33: =IF(C33="", "", ROUND(IF(C33=6, SUM(OFFSET(H32, -4, 0):H32)*1%, IF(C33>6,H32*1%, 0)),0)) -> 243 | M33: =IF(C33="", "", L33*VLOOKUP(C33, $U$4:$V$9, 2)) -> 0 | N33: =IF(C33="", "", MAX(I33-SUM(L$17:L32), 0)) -> 768300 | O33: =IF($C33="", "", IF(AND($C33>1, Q32<=0), 0, Q32+SUM($E33:$H33)-$J33+K33)) -> 899749.16 | P33: =IF($C33="", "", IF(O33<=0, 0, MAX(VLOOKUP($D33-1, $R$4:$S$7, 2)*$N33-O33, 0)*OFFSET(鑫意锁风险保险费!$B$5, $D33-1, IF($D$3="男", 1, 2))/1000)) -> 464.29902 | Q33: =IF($C33="", "", MAX((O33-P33)*(1+2%)-L33, 0)) -> 917270.56 | R33: =IF($C33="", "", Q33*(1-VLOOKUP($C33, $U$4:$V$9, 2))) -> 917270.56 | S33: =IF($C33="", "", IF(Q33<=0, 0, MAX(VLOOKUP($D33, $R$4:$S$7, 2)*N33, Q33))) -> 1075620 | T33: =IF($C33="", "", IF(AND($C33>1, V32<=0), 0, V32+SUM($E33:$H33)-$J33+K33)) -> 1072480.6 | U33: =IF($C33="", "", IF(T33<=0, 0, MAX(VLOOKUP($D33-1, $R$4:$S$7, 2)*$N33-T33, 0)*OFFSET(鑫意锁风险保险费!$B$5, $D33-1, IF($D$3="男", 1, 2))/1000)) -> 8.2878967 | V33: =IF($C33="", "", MAX((T33-U33)*(1+4%)-$L33, 0)) -> 1115371.3 | W33: =IF($C33="", "", V33*(1-VLOOKUP($C33, $U$4:$V$9, 2))) -> 1115371.3 | X33: =IF($C33="", "", IF(V33<=0, 0, MAX(VLOOKUP($D33, $R$4:$S$7, 2)*$N33, V33))) -> 1115371.3
C34: =IF(AND(C33>0, C33<99-$H$3), C33+1,"") -> 17 | D34: =IF(C34="","",D33+1) -> 47 | E34: =IF(C34="", "", IF(C34=1, $F$6, 0)) -> 0 | H34: =IF(C34="", "", IF(AND(C34>=6, D34<=60), OFFSET(利益演示!$G$16, C34-1, 0), IF(D34>60, OFFSET(利益演示!$H$16, C34-1, 0), 0))) -> 24300 | I34: =IF(C34="", "", SUM($E$18:H34)) -> 792600 | J34: =IF(C34="","",E34*1%+F34*1%+G34*3%+H34*1%) -> 243 | K34: =IF(C34="", "", ROUND(IF(C34=6, SUM(OFFSET(H33, -4, 0):H33)*1%, IF(C34>6,H33*1%, 0)),0)) -> 243 | M34: =IF(C34="", "", L34*VLOOKUP(C34, $U$4:$V$9, 2)) -> 0 | N34: =IF(C34="", "", MAX(I34-SUM(L$17:L33), 0)) -> 792600 | O34: =IF($C34="", "", IF(AND($C34>1, Q33<=0), 0, Q33+SUM($E34:$H34)-$J34+K34)) -> 941570.56 | P34: =IF($C34="", "", IF(O34<=0, 0, MAX(VLOOKUP($D34-1, $R$4:$S$7, 2)*$N34-O34, 0)*OFFSET(鑫意锁风险保险费!$B$5, $D34-1, IF($D$3="男", 1, 2))/1000)) -> 489.08208 | Q34: =IF($C34="", "", MAX((O34-P34)*(1+2%)-L34, 0)) -> 959903.11 | R34: =IF($C34="", "", Q34*(1-VLOOKUP($C34, $U$4:$V$9, 2))) -> 959903.11 | S34: =IF($C34="", "", IF(Q34<=0, 0, MAX(VLOOKUP($D34, $R$4:$S$7, 2)*N34, Q34))) -> 1109640 | T34: =IF($C34="", "", IF(AND($C34>1, V33<=0), 0, V33+SUM($E34:$H34)-$J34+K34)) -> 1139671.3 | U34: =IF($C34="", "", IF(T34<=0, 0, MAX(VLOOKUP($D34-1, $R$4:$S$7, 2)*$N34-T34, 0)*OFFSET(鑫意锁风险保险费!$B$5, $D34-1, IF($D$3="男", 1, 2))/1000)) -> 0 | V34: =IF($C34="", "", MAX((T34-U34)*(1+4%)-$L34, 0)) -> 1185258.1 | W34: =IF($C34="", "", V34*(1-VLOOKUP($C34, $U$4:$V$9, 2))) -> 1185258.1 | X34: =IF($C34="", "", IF(V34<=0, 0, MAX(VLOOKUP($D34, $R$4:$S$7, 2)*$N34, V34))) -> 1185258.1
C35: =IF(AND(C34>0, C34<99-$H$3), C34+1,"") -> 18 | D35: =IF(C35="","",D34+1) -> 48 | E35: =IF(C35="", "", IF(C35=1, $F$6, 0)) -> 0 | H35: =IF(C35="", "", IF(AND(C35>=6, D35<=60), OFFSET(利益演示!$G$16, C35-1, 0), IF(D35>60, OFFSET(利益演示!$H$16, C35-1, 0), 0))) -> 24300 | I35: =IF(C35="", "", SUM($E$18:H35)) -> 816900 | J35: =IF(C35="","",E35*1%+F35*1%+G35*3%+H35*1%) -> 243 | K35: =IF(C35="", "", ROUND(IF(C35=6, SUM(OFFSET(H34, -4, 0):H34)*1%, IF(C35>6,H34*1%, 0)),0)) -> 243 | M35: =IF(C35="", "", L35*VLOOKUP(C35, $U$4:$V$9, 2)) -> 0 | N35: =IF(C35="", "", MAX(I35-SUM(L$17:L34), 0)) -> 816900 | O35: =IF($C35="", "", IF(AND($C35>1, Q34<=0), 0, Q34+SUM($E35:$H35)-$J35+K35)) -> 984203.11 | P35: =IF($C35="", "", IF(O35<=0, 0, MAX(VLOOKUP($D35-1, $R$4:$S$7, 2)*$N35-O35, 0)*OFFSET(鑫意锁风险保险费!$B$5, $D35-1, IF($D$3="男", 1, 2))/1000)) -> 511.85663 | Q35: =IF($C35="", "", MAX((O35-P35)*(1+2%)-L35, 0)) -> 1003365.1 | R35: =IF($C35="", "", Q35*(1-VLOOKUP($C35, $U$4:$V$9, 2))) -> 1003365.1 | S35: =IF($C35="", "", IF(Q35<=0, 0, MAX(VLOOKUP($D35, $R$4:$S$7, 2)*N35, Q35))) -> 1143660 | T35: =IF($C35="", "", IF(AND($C35>1, V34<=0), 0, V34+SUM($E35:$H35)-$J35+K35)) -> 1209558.1 | U35: =IF($C35="", "", IF(T35<=0, 0, MAX(VLOOKUP($D35-1, $R$4:$S$7, 2)*$N35-T35, 0)*OFFSET(鑫意锁风险保险费!$B$5, $D35-1, IF($D$3="男", 1, 2))/1000)) -> 0 | V35: =IF($C35="", "", MAX((T35-U35)*(1+4%)-$L35, 0)) -> 1257940.4 | W35: =IF($C35="", "", V35*(1-VLOOKUP($C35, $U$4:$V$9, 2))) -> 1257940.4 | X35: =IF($C35="", "", IF(V35<=0, 0, MAX(VLOOKUP($D35, $R$4:$S$7, 2)*$N35, V35))) -> 1257940.4
C36: =IF(AND(C35>0, C35<99-$H$3), C35+1,"") -> 19 | D36: =IF(C36="","",D35+1) -> 49 | E36: =IF(C36="", "", IF(C36=1, $F$6, 0)) -> 0 | H36: =IF(C36="", "", IF(AND(C36>=6, D36<=60), OFFSET(利益演示!$G$16, C36-1, 0), IF(D36>60, OFFSET(利益演示!$H$16, C36-1, 0), 0))) -> 24300 | I36: =IF(C36="", "", SUM($E$18:H36)) -> 841200 | J36: =IF(C36="","",E36*1%+F36*1%+G36*3%+H36*1%) -> 243 | K36: =IF(C36="", "", ROUND(IF(C36=6, SUM(OFFSET(H35, -4, 0):H35)*1%, IF(C36>6,H35*1%, 0)),0)) -> 243 | M36: =IF(C36="", "", L36*VLOOKUP(C36, $U$4:$V$9, 2)) -> 0 | N36: =IF(C36="", "", MAX(I36-SUM(L$17:L35), 0)) -> 841200 | O36: =IF($C36="", "", IF(AND($C36>1, Q35<=0), 0, Q35+SUM($E36:$H36)-$J36+K36)) -> 1027665.1 | P36: =IF($C36="", "", IF(O36<=0, 0, MAX(VLOOKUP($D36-1, $R$4:$S$7, 2)*$N36-O36, 0)*OFFSET(鑫意锁风险保险费!$B$5, $D36-1, IF($D$3="男", 1, 2))/1000)) -> 531.05284 | Q36: =IF($C36="", "", MAX((O36-P36)*(1+2%)-L36, 0)) -> 1047676.7 | R36: =IF($C36="", "", Q36*(1-VLOOKUP($C36, $U$4:$V$9, 2))) -> 1047676.7 | S36: =IF($C36="", "", IF(Q36<=0, 0, MAX(VLOOKUP($D36, $R$4:$S$7, 2)*N36, Q36))) -> 1177680 | T36: =IF($C36="", "", IF(AND($C36>1, V35<=0), 0, V35+SUM($E36:$H36)-$J36+K36)) -> 1282240.4 | U36: =IF($C36="", "", IF(T36<=0, 0, MAX(VLOOKUP($D36-1, $R$4:$S$7, 2)*$N36-T36, 0)*OFFSET(鑫意锁风险保险费!$B$5, $D36-1, IF($D$3="男", 1, 2))/1000)) -> 0 | V36: =IF($C36="", "", MAX((T36-U36)*(1+4%)-$L36, 0)) -> 1333530 | W36: =IF($C36="", "", V36*(1-VLOOKUP($C36, $U$4:$V$9, 2))) -> 1333530 | X36: =IF($C36="", "", IF(V36<=0, 0, MAX(VLOOKUP($D36, $R$4:$S$7, 2)*$N36, V36))) -> 1333530
... C41: =IF(AND(C40>0, C40<99-$H$3), C40+1,"") -> 24 | D41: =IF(C41="","",D40+1) -> 54 | E41: =IF(C41="", "", IF(C41=1, $F$6, 0)) -> 0 | H41: =IF(C41="", "", IF(AND(C41>=6, D41<=60), OFFSET(利益演示!$G$16, C41-1, 0), IF(D41>60, OFFSET(利益演示!$H$16, C41-1, 0), 0))) -> 24300 | I41: =IF(C41="", "", SUM($E$18:H41)) -> 962700 | J41: =IF(C41="","",E41*1%+F41*1%+G41*3%+H41*1%) -> 243 | K41: =IF(C41="", "", ROUND(IF(C41=6, SUM(OFFSET(H40, -4, 0):H40)*1%, IF(C41>6,H40*1%, 0)),0)) -> 243 | M41: =IF(C41="", "", L41*VLOOKUP(C41, $U$4:$V$9, 2)) -> 0 | N41: =IF(C41="", "", MAX(I41-SUM(L$17:L40), 0)) -> 962700 | O41: =IF($C41="", "", IF(AND($C41>1, Q40<=0), 0, Q40+SUM($E41:$H41)-$J41+K41)) -> 1258238.4 | P41: =IF($C41="", "", IF(O41<=0, 0, MAX(VLOOKUP($D41-1, $R$4:$S$7, 2)*$N41-O41, 0)*OFFSET(鑫意锁风险保险费!$B$5, $D41-1, IF($D$3="男", 1, 2))/1000)) -> 488.00189 | Q41: =IF($C41="", "", MAX((O41-P41)*(1+2%)-L41, 0)) -> 1282905.4 | R41: =IF($C41="", "", Q41*(1-VLOOKUP($C41, $U$4:$V$9, 2))) -> 1282905.4 | S41: =IF($C41="", "", IF(Q41<=0, 0, MAX(VLOOKUP($D41, $R$4:$S$7, 2)*N41, Q41))) -> 1347780 | T41: =IF($C41="", "", IF(AND($C41>1, V40<=0), 0, V40+SUM($E41:$H41)-$J41+K41)) -> 1691658.2 | U41: =IF($C41="", "", IF(T41<=0, 0, MAX(VLOOKUP($D41-1, $R$4:$S$7, 2)*$N41-T41, 0)*OFFSET(鑫意锁风险保险费!$B$5, $D41-1, IF($D$3="男", 1, 2))/1000)) -> 0 | V41: =IF($C41="", "", MAX((T41-U41)*(1+4%)-$L41, 0)) -> 1759324.5 | W41: =IF($C41="", "", V41*(1-VLOOKUP($C41, $U$4:$V$9, 2))) -> 1759324.5 | X41: =IF($C41="", "", IF(V41<=0, 0, MAX(VLOOKUP($D41, $R$4:$S$7, 2)*$N41, V41))) -> 1759324.5
C42: =IF(AND(C41>0, C41<99-$H$3), C41+1,"") -> 25 | D42: =IF(C42="","",D41+1) -> 55 | E42: =IF(C42="", "", IF(C42=1, $F$6, 0)) -> 0 | H42: =IF(C42="", "", IF(AND(C42>=6, D42<=60), OFFSET(利益演示!$G$16, C42-1, 0), IF(D42>60, OFFSET(利益演示!$H$16, C42-1, 0), 0))) -> 24300 | I42: =IF(C42="", "", SUM($E$18:H42)) -> 987000 | J42: =IF(C42="","",E42*1%+F42*1%+G42*3%+H42*1%) -> 243 | K42: =IF(C42="", "", ROUND(IF(C42=6, SUM(OFFSET(H41, -4, 0):H41)*1%, IF(C42>6,H41*1%, 0)),0)) -> 243 | L42: 100000 | M42: =IF(C42="", "", L42*VLOOKUP(C42, $U$4:$V$9, 2)) -> 0 | N42: =IF(C42="", "", MAX(I42-SUM(L$17:L41), 0)) -> 987000 | O42: =IF($C42="", "", IF(AND($C42>1, Q41<=0), 0, Q41+SUM($E42:$H42)-$J42+K42)) -> 1307205.4 | P42: =IF($C42="", "", IF(O42<=0, 0, MAX(VLOOKUP($D42-1, $R$4:$S$7, 2)*$N42-O42, 0)*OFFSET(鑫意锁风险保险费!$B$5, $D42-1, IF($D$3="男", 1, 2))/1000)) -> 437.87045 | Q42: =IF($C42="", "", MAX((O42-P42)*(1+2%)-L42, 0)) -> 1232902.9 | R42: =IF($C42="", "", Q42*(1-VLOOKUP($C42, $U$4:$V$9, 2))) -> 1232902.9 | S42: =IF($C42="", "", IF(Q42<=0, 0, MAX(VLOOKUP($D42, $R$4:$S$7, 2)*N42, Q42))) -> 1381800 | T42: =IF($C42="", "", IF(AND($C42>1, V41<=0), 0, V41+SUM($E42:$H42)-$J42+K42)) -> 1783624.5 | U42: =IF($C42="", "", IF(T42<=0, 0, MAX(VLOOKUP($D42-1, $R$4:$S$7, 2)*$N42-T42, 0)*OFFSET(鑫意锁风险保险费!$B$5, $D42-1, IF($D$3="男", 1, 2))/1000)) -> 0 | V42: =IF($C42="", "", MAX((T42-U42)*(1+4%)-$L42, 0)) -> 1754969.5 | W42: =IF($C42="", "", V42*(1-VLOOKUP($C42, $U$4:$V$9, 2))) -> 1754969.5 | X42: =IF($C42="", "", IF(V42<=0, 0, MAX(VLOOKUP($D42, $R$4:$S$7, 2)*$N42, V42))) -> 1754969.5
C43: =IF(AND(C42>0, C42<99-$H$3), C42+1,"") -> 26 | D43: =IF(C43="","",D42+1) -> 56 | E43: =IF(C43="", "", IF(C43=1, $F$6, 0)) -> 0 | H43: =IF(C43="", "", IF(AND(C43>=6, D43<=60), OFFSET(利益演示!$G$16, C43-1, 0), IF(D43>60, OFFSET(利益演示!$H$16, C43-1, 0), 0))) -> 24300 | I43: =IF(C43="", "", SUM($E$18:H43)) -> 1011300 | J43: =IF(C43="","",E43*1%+F43*1%+G43*3%+H43*1%) -> 243 | K43: =IF(C43="", "", ROUND(IF(C43=6, SUM(OFFSET(H42, -4, 0):H42)*1%, IF(C43>6,H42*1%, 0)),0)) -> 243 | L43: 100000 | M43: =IF(C43="", "", L43*VLOOKUP(C43, $U$4:$V$9, 2)) -> 0 | N43: =IF(C43="", "", MAX(I43-SUM(L$17:L42), 0)) -> 911300 | O43: =IF($C43="", "", IF(AND($C43>1, Q42<=0), 0, Q42+SUM($E43:$H43)-$J43+K43)) -> 1257202.9 | P43: =IF($C43="", "", IF(O43<=0, 0, MAX(VLOOKUP($D43-1, $R$4:$S$7, 2)*$N43-O43, 0)*OFFSET(鑫意锁风险保险费!$B$5, $D43-1, IF($D$3="男", 1, 2))/1000)) -> 117.28802 | Q43: =IF($C43="", "", MAX((O43-P43)*(1+2%)-L43, 0)) -> 1182227.3 | R43: =IF($C43="", "", Q43*(1-VLOOKUP($C43, $U$4:$V$9, 2))) -> 1182227.3 | S43: =IF($C43="", "", IF(Q43<=0, 0, MAX(VLOOKUP($D43, $R$4:$S$7, 2)*N43, Q43))) -> 1275820 | T43: =IF($C43="", "", IF(AND($C43>1, V42<=0), 0, V42+SUM($E43:$H43)-$J43+K43)) -> 1779269.5 | U43: =IF($C43="", "", IF(T43<=0, 0, MAX(VLOOKUP($D43-1, $R$4:$S$7, 2)*$N43-T43, 0)*OFFSET(鑫意锁风险保险费!$B$5, $D43-1, IF($D$3="男", 1, 2))/1000)) -> 0 | V43: =IF($C43="", "", MAX((T43-U43)*(1+4%)-$L43, 0)) -> 1750440.3 | W43: =IF($C43="", "", V43*(1-VLOOKUP($C43, $U$4:$V$9, 2))) -> 1750440.3 | X43: =IF($C43="", "", IF(V43<=0, 0, MAX(VLOOKUP($D43, $R$4:$S$7, 2)*$N43, V43))) -> 1750440.3
C44: =IF(AND(C43>0, C43<99-$H$3), C43+1,"") -> 27 | D44: =IF(C44="","",D43+1) -> 57 | E44: =IF(C44="", "", IF(C44=1, $F$6, 0)) -> 0 | H44: =IF(C44="", "", IF(AND(C44>=6, D44<=60), OFFSET(利益演示!$G$16, C44-1, 0), IF(D44>60, OFFSET(利益演示!$H$16, C44-1, 0), 0))) -> 24300 | I44: =IF(C44="", "", SUM($E$18:H44)) -> 1035600 | J44: =IF(C44="","",E44*1%+F44*1%+G44*3%+H44*1%) -> 243 | K44: =IF(C44="", "", ROUND(IF(C44=6, SUM(OFFSET(H43, -4, 0):H43)*1%, IF(C44>6,H43*1%, 0)),0)) -> 243 | L44: 100000 | M44: =IF(C44="", "", L44*VLOOKUP(C44, $U$4:$V$9, 2)) -> 0 | N44: =IF(C44="", "", MAX(I44-SUM(L$17:L43), 0)) -> 835600 | O44: =IF($C44="", "", IF(AND($C44>1, Q43<=0), 0, Q43+SUM($E44:$H44)-$J44+K44)) -> 1206527.3 | P44: =IF($C44="", "", IF(O44<=0, 0, MAX(VLOOKUP($D44-1, $R$4:$S$7, 2)*$N44-O44, 0)*OFFSET(鑫意锁风险保险费!$B$5, $D44-1, IF($D$3="男", 1, 2))/1000)) -> 0 | Q44: =IF($C44="", "", MAX((O44-P44)*(1+2%)-L44, 0)) -> 1130657.8 | R44: =IF($C44="", "", Q44*(1-VLOOKUP($C44, $U$4:$V$9, 2))) -> 1130657.8 | S44: =IF($C44="", "", IF(Q44<=0, 0, MAX(VLOOKUP($D44, $R$4:$S$7, 2)*N44, Q44))) -> 1169840 | T44: =IF($C44="", "", IF(AND($C44>1, V43<=0), 0, V43+SUM($E44:$H44)-$J44+K44)) -> 1774740.3 | U44: =IF($C44="", "", IF(T44<=0, 0, MAX(VLOOKUP($D44-1, $R$4:$S$7, 2)*$N44-T44, 0)*OFFSET(鑫意锁风险保险费!$B$5, $D44-1, IF($D$3="男", 1, 2))/1000)) -> 0 | V44: =IF($C44="", "", MAX((T44-U44)*(1+4%)-$L44, 0)) -> 1745729.9 | W44: =IF($C44="", "", V44*(1-VLOOKUP($C44, $U$4:$V$9, 2))) -> 1745729.9 | X44: =IF($C44="", "", IF(V44<=0, 0, MAX(VLOOKUP($D44, $R$4:$S$7, 2)*$N44, V44))) -> 1745729.9
C45: =IF(AND(C44>0, C44<99-$H$3), C44+1,"") -> 28 | D45: =IF(C45="","",D44+1) -> 58 | E45: =IF(C45="", "", IF(C45=1, $F$6, 0)) -> 0 | H45: =IF(C45="", "", IF(AND(C45>=6, D45<=60), OFFSET(利益演示!$G$16, C45-1, 0), IF(D45>60, OFFSET(利益演示!$H$16, C45-1, 0), 0))) -> 24300 | I45: =IF(C45="", "", SUM($E$18:H45)) -> 1059900 | J45: =IF(C45="","",E45*1%+F45*1%+G45*3%+H45*1%) -> 243 | K45: =IF(C45="", "", ROUND(IF(C45=6, SUM(OFFSET(H44, -4, 0):H44)*1%, IF(C45>6,H44*1%, 0)),0)) -> 243 | L45: 100000 | M45: =IF(C45="", "", L45*VLOOKUP(C45, $U$4:$V$9, 2)) -> 0 | N45: =IF(C45="", "", MAX(I45-SUM(L$17:L44), 0)) -> 759900 | O45: =IF($C45="", "", IF(AND($C45>1, Q44<=0), 0, Q44+SUM($E45:$H45)-$J45+K45)) -> 1154957.8 | P45: =IF($C45="", "", IF(O45<=0, 0, MAX(VLOOKUP($D45-1, $R$4:$S$7, 2)*$N45-O45, 0)*OFFSET(鑫意锁风险保险费!$B$5, $D45-1, IF($D$3="男", 1, 2))/1000)) -> 0 | Q45: =IF($C45="", "", MAX((O45-P45)*(1+2%)-L45, 0)) -> 1078057 | R45: =IF($C45="", "", Q45*(1-VLOOKUP($C45, $U$4:$V$9, 2))) -> 1078057 | S45: =IF($C45="", "", IF(Q45<=0, 0, MAX(VLOOKUP($D45, $R$4:$S$7, 2)*N45, Q45))) -> 1078057 | T45: =IF($C45="", "", IF(AND($C45>1, V44<=0), 0, V44+SUM($E45:$H45)-$J45+K45)) -> 1770029.9 | U45: =IF($C45="", "", IF(T45<=0, 0, MAX(VLOOKUP($D45-1, $R$4:$S$7, 2)*$N45-T45, 0)*OFFSET(鑫意锁风险保险费!$B$5, $D45-1, IF($D$3="男", 1, 2))/1000)) -> 0 | V45: =IF($C45="", "", MAX((T45-U45)*(1+4%)-$L45, 0)) -> 1740831.1 | W45: =IF($C45="", "", V45*(1-VLOOKUP($C45, $U$4:$V$9, 2))) -> 1740831.1 | X45: =IF($C45="", "", IF(V45<=0, 0, MAX(VLOOKUP($D45, $R$4:$S$7, 2)*$N45, V45))) -> 1740831.1
C46: =IF(AND(C45>0, C45<99-$H$3), C45+1,"") -> 29 | D46: =IF(C46="","",D45+1) -> 59 | E46: =IF(C46="", "", IF(C46=1, $F$6, 0)) -> 0 | H46: =IF(C46="", "", IF(AND(C46>=6, D46<=60), OFFSET(利益演示!$G$16, C46-1, 0), IF(D46>60, OFFSET(利益演示!$H$16, C46-1, 0), 0))) -> 24300 | I46: =IF(C46="", "", SUM($E$18:H46)) -> 1084200 | J46: =IF(C46="","",E46*1%+F46*1%+G46*3%+H46*1%) -> 243 | K46: =IF(C46="", "", ROUND(IF(C46=6, SUM(OFFSET(H45, -4, 0):H45)*1%, IF(C46>6,H45*1%, 0)),0)) -> 243 | L46: 100000 | M46: =IF(C46="", "", L46*VLOOKUP(C46, $U$4:$V$9, 2)) -> 0 | N46: =IF(C46="", "", MAX(I46-SUM(L$17:L45), 0)) -> 684200 | O46: =IF($C46="", "", IF(AND($C46>1, Q45<=0), 0, Q45+SUM($E46:$H46)-$J46+K46)) -> 1102357 | P46: =IF($C46="", "", IF(O46<=0, 0, MAX(VLOOKUP($D46-1, $R$4:$S$7, 2)*$N46-O46, 0)*OFFSET(鑫意锁风险保险费!$B$5, $D46-1, IF($D$3="男", 1, 2))/1000)) -> 0 | Q46: =IF($C46="", "", MAX((O46-P46)*(1+2%)-L46, 0)) -> 1024404.1 | R46: =IF($C46="", "", Q46*(1-VLOOKUP($C46, $U$4:$V$9, 2))) -> 1024404.1 | S46: =IF($C46="", "", IF(Q46<=0, 0, MAX(VLOOKUP($D46, $R$4:$S$7, 2)*N46, Q46))) -> 1024404.1 | T46: =IF($C46="", "", IF(AND($C46>1, V45<=0), 0, V45+SUM($E46:$H46)-$J46+K46)) -> 1765131.1 | U46: =IF($C46="", "", IF(T46<=0, 0, MAX(VLOOKUP($D46-1, $R$4:$S$7, 2)*$N46-T46, 0)*OFFSET(鑫意锁风险保险费!$B$5, $D46-1, IF($D$3="男", 1, 2))/1000)) -> 0 | V46: =IF($C46="", "", MAX((T46-U46)*(1+4%)-$L46, 0)) -> 1735736.3 | W46: =IF($C46="", "", V46*(1-VLOOKUP($C46, $U$4:$V$9, 2))) -> 1735736.3 | X46: =IF($C46="", "", IF(V46<=0, 0, MAX(VLOOKUP($D46, $R$4:$S$7, 2)*$N46, V46))) -> 1735736.3
C47: =IF(AND(C46>0, C46<99-$H$3), C46+1,"") -> 30 | D47: =IF(C47="","",D46+1) -> 60 | E47: =IF(C47="", "", IF(C47=1, $F$6, 0)) -> 0 | H47: =IF(C47="", "", IF(AND(C47>=6, D47<=60), OFFSET(利益演示!$G$16, C47-1, 0), IF(D47>60, OFFSET(利益演示!$H$16, C47-1, 0), 0))) -> 24300 | I47: =IF(C47="", "", SUM($E$18:H47)) -> 1108500 | J47: =IF(C47="","",E47*1%+F47*1%+G47*3%+H47*1%) -> 243 | K47: =IF(C47="", "", ROUND(IF(C47=6, SUM(OFFSET(H46, -4, 0):H46)*1%, IF(C47>6,H46*1%, 0)),0)) -> 243 | L47: 100000 | M47: =IF(C47="", "", L47*VLOOKUP(C47, $U$4:$V$9, 2)) -> 0 | N47: =IF(C47="", "", MAX(I47-SUM(L$17:L46), 0)) -> 608500 | O47: =IF($C47="", "", IF(AND($C47>1, Q46<=0), 0, Q46+SUM($E47:$H47)-$J47+K47)) -> 1048704.1 | P47: =IF($C47="", "", IF(O47<=0, 0, MAX(VLOOKUP($D47-1, $R$4:$S$7, 2)*$N47-O47, 0)*OFFSET(鑫意锁风险保险费!$B$5, $D47-1, IF($D$3="男", 1, 2))/1000)) -> 0 | Q47: =IF($C47="", "", MAX((O47-P47)*(1+2%)-L47, 0)) -> 969678.2 | R47: =IF($C47="", "", Q47*(1-VLOOKUP($C47, $U$4:$V$9, 2))) -> 969678.2 | S47: =IF($C47="", "", IF(Q47<=0, 0, MAX(VLOOKUP($D47, $R$4:$S$7, 2)*N47, Q47))) -> 969678.2 | T47: =IF($C47="", "", IF(AND($C47>1, V46<=0), 0, V46+SUM($E47:$H47)-$J47+K47)) -> 1760036.3 | U47: =IF($C47="", "", IF(T47<=0, 0, MAX(VLOOKUP($D47-1, $R$4:$S$7, 2)*$N47-T47, 0)*OFFSET(鑫意锁风险保险费!$B$5, $D47-1, IF($D$3="男", 1, 2))/1000)) -> 0 | V47: =IF($C47="", "", MAX((T47-U47)*(1+4%)-$L47, 0)) -> 1730437.8 | W47: =IF($C47="", "", V47*(1-VLOOKUP($C47, $U$4:$V$9, 2))) -> 1730437.8 | X47: =IF($C47="", "", IF(V47<=0, 0, MAX(VLOOKUP($D47, $R$4:$S$7, 2)*$N47, V47))) -> 1730437.8
C48: =IF(AND(C47>0, C47<99-$H$3), C47+1,"") -> 31 | D48: =IF(C48="","",D47+1) -> 61 | E48: =IF(C48="", "", IF(C48=1, $F$6, 0)) -> 0 | H48: =IF(C48="", "", IF(AND(C48>=6, D48<=60), OFFSET(利益演示!$G$16, C48-1, 0), IF(D48>60, OFFSET(利益演示!$H$16, C48-1, 0), 0))) -> 48600 | I48: =IF(C48="", "", SUM($E$18:H48)) -> 1157100 | J48: =IF(C48="","",E48*1%+F48*1%+G48*3%+H48*1%) -> 486 | K48: =IF(C48="", "", ROUND(IF(C48=6, SUM(OFFSET(H47, -4, 0):H47)*1%, IF(C48>6,H47*1%, 0)),0)) -> 243 | L48: 100000 | M48: =IF(C48="", "", L48*VLOOKUP(C48, $U$4:$V$9, 2)) -> 0 | N48: =IF(C48="", "", MAX(I48-SUM(L$17:L47), 0)) -> 557100 | O48: =IF($C48="", "", IF(AND($C48>1, Q47<=0), 0, Q47+SUM($E48:$H48)-$J48+K48)) -> 1018035.2 | P48: =IF($C48="", "", IF(O48<=0, 0, MAX(VLOOKUP($D48-1, $R$4:$S$7, 2)*$N48-O48, 0)*OFFSET(鑫意锁风险保险费!$B$5, $D48-1, IF($D$3="男", 1, 2))/1000)) -> 0 | Q48: =IF($C48="", "", MAX((O48-P48)*(1+2%)-L48, 0)) -> 938395.91 | R48: =IF($C48="", "", Q48*(1-VLOOKUP($C48, $U$4:$V$9, 2))) -> 938395.91 | S48: =IF($C48="", "", IF(Q48<=0, 0, MAX(VLOOKUP($D48, $R$4:$S$7, 2)*N48, Q48))) -> 938395.91 | T48: =IF($C48="", "", IF(AND($C48>1, V47<=0), 0, V47+SUM($E48:$H48)-$J48+K48)) -> 1778794.8 | U48: =IF($C48="", "", IF(T48<=0, 0, MAX(VLOOKUP($D48-1, $R$4:$S$7, 2)*$N48-T48, 0)*OFFSET(鑫意锁风险保险费!$B$5, $D48-1, IF($D$3="男", 1, 2))/1000)) -> 0 | V48: =IF($C48="", "", MAX((T48-U48)*(1+4%)-$L48, 0)) -> 1749946.6 | W48: =IF($C48="", "", V48*(1-VLOOKUP($C48, $U$4:$V$9, 2))) -> 1749946.6 | X48: =IF($C48="", "", IF(V48<=0, 0, MAX(VLOOKUP($D48, $R$4:$S$7, 2)*$N48, V48))) -> 1749946.6
C49: =IF(AND(C48>0, C48<99-$H$3), C48+1,"") -> 32 | D49: =IF(C49="","",D48+1) -> 62 | E49: =IF(C49="", "", IF(C49=1, $F$6, 0)) -> 0 | H49: =IF(C49="", "", IF(AND(C49>=6, D49<=60), OFFSET(利益演示!$G$16, C49-1, 0), IF(D49>60, OFFSET(利益演示!$H$16, C49-1, 0), 0))) -> 48600 | I49: =IF(C49="", "", SUM($E$18:H49)) -> 1205700 | J49: =IF(C49="","",E49*1%+F49*1%+G49*3%+H49*1%) -> 486 | K49: =IF(C49="", "", ROUND(IF(C49=6, SUM(OFFSET(H48, -4, 0):H48)*1%, IF(C49>6,H48*1%, 0)),0)) -> 486 | L49: 100000 | M49: =IF(C49="", "", L49*VLOOKUP(C49, $U$4:$V$9, 2)) -> 0 | N49: =IF(C49="", "", MAX(I49-SUM(L$17:L48), 0)) -> 505700 | O49: =IF($C49="", "", IF(AND($C49>1, Q48<=0), 0, Q48+SUM($E49:$H49)-$J49+K49)) -> 986995.91 | P49: =IF($C49="", "", IF(O49<=0, 0, MAX(VLOOKUP($D49-1, $R$4:$S$7, 2)*$N49-O49, 0)*OFFSET(鑫意锁风险保险费!$B$5, $D49-1, IF($D$3="男", 1, 2))/1000)) -> 0 | Q49: =IF($C49="", "", MAX((O49-P49)*(1+2%)-L49, 0)) -> 906735.82 | R49: =IF($C49="", "", Q49*(1-VLOOKUP($C49, $U$4:$V$9, 2))) -> 906735.82 | S49: =IF($C49="", "", IF(Q49<=0, 0, MAX(VLOOKUP($D49, $R$4:$S$7, 2)*N49, Q49))) -> 906735.82 | T49: =IF($C49="", "", IF(AND($C49>1, V48<=0), 0, V48+SUM($E49:$H49)-$J49+K49)) -> 1798546.6 | U49: =IF($C49="", "", IF(T49<=0, 0, MAX(VLOOKUP($D49-1, $R$4:$S$7, 2)*$N49-T49, 0)*OFFSET(鑫意锁风险保险费!$B$5, $D49-1, IF($D$3="男", 1, 2))/1000)) -> 0 | V49: =IF($C49="", "", MAX((T49-U49)*(1+4%)-$L49, 0)) -> 1770488.4 | W49: =IF($C49="", "", V49*(1-VLOOKUP($C49, $U$4:$V$9, 2))) -> 1770488.4 | X49: =IF($C49="", "", IF(V49<=0, 0, MAX(VLOOKUP($D49, $R$4:$S$7, 2)*$N49, V49))) -> 1770488.4
...

Sheet 鑫意锁风险保险费
B4: 年龄 | C4: 男 | D4: 女
B5: 0 | C5: 0.87 | D5: 0.62
B6: 1 | C6: 0.62 | D6: 0.46
B7: 2 | C7: 0.45 | D7: 0.34
B8: 3 | C8: 0.34 | D8: 0.26
B9: 4 | C9: 0.28 | D9: 0.2
B10: 5 | C10: 0.25 | D10: 0.17
B11: 6 | C11: 0.24 | D11: 0.15
B12: 7 | C12: 0.23 | D12: 0.14
B13: 8 | C13: 0.24 | D13: 0.13
B14: 9 | C14: 0.25 | D14: 0.14
B15: 10 | C15: 0.27 | D15: 0.15
B16: 11 | C16: 0.29 | D16: 0.16
... B104: 99 | C104: 417.26 | D104: 319.79

Sheet 保费保额表
C1: PPP | D1: SEX | E1: AGE | F1: 费率表 | G1: 保额表 | J1: 交费期间 | K1: 最高投保年龄
B2: =C2&"_"&D2&"_"&E2 -> 1_男_0 | C2: 1 | D2: 男 | E2: 0 | F2: 32552 | G2: 31 | J2: 一次性付清 | K2: 50
B3: =C3&"_"&D3&"_"&E3 -> 1_男_1 | C3: 1 | D3: 男 | E3: 1 | F3: 32562.8 | G3: 31 | J3: 3年交 | K3: 50
B4: =C4&"_"&D4&"_"&E4 -> 1_男_2 | C4: 1 | D4: 男 | E4: 2 | F4: 32574.1 | G4: 31 | J4: 5年交 | K4: 50
B5: =C5&"_"&D5&"_"&E5 -> 1_男_3 | C5: 1 | D5: 男 | E5: 3 | F5: 32585.9 | G5: 31 | J5: 10年交 | K5: 45
B6: =C6&"_"&D6&"_"&E6 -> 1_男_4 | C6: 1 | D6: 男 | E6: 4 | F6: 32598.2 | G6: 31
B7: =C7&"_"&D7&"_"&E7 -> 1_男_5 | C7: 1 | D7: 男 | E7: 5 | F7: 32610.8 | G7: 31
B8: =C8&"_"&D8&"_"&E8 -> 1_男_6 | C8: 1 | D8: 男 | E8: 6 | F8: 32623.9 | G8: 31
B9: =C9&"_"&D9&"_"&E9 -> 1_男_7 | C9: 1 | D9: 男 | E9: 7 | F9: 32637.5 | G9: 31
B10: =C10&"_"&D10&"_"&E10 -> 1_男_8 | C10: 1 | D10: 男 | E10: 8 | F10: 32651.6 | G10: 31
B11: =C11&"_"&D11&"_"&E11 -> 1_男_9 | C11: 1 | D11: 男 | E11: 9 | F11: 32666.1 | G11: 31
B12: =C12&"_"&D12&"_"&E12 -> 1_男_10 | C12: 1 | D12: 男 | E12: 10 | F12: 32681.2 | G12: 31
B13: =C13&"_"&D13&"_"&E13 -> 1_男_11 | C13: 1 | D13: 男 | E13: 11 | F13: 32696.8 | G13: 31
B14: =C14&"_"&D14&"_"&E14 -> 1_男_12 | C14: 1 | D14: 男 | E14: 12 | F14: 32712.9 | G14: 31
B15: =C15&"_"&D15&"_"&E15 -> 1_男_13 | C15: 1 | D15: 男 | E15: 13 | F15: 32729.5 | G15: 31
B16: =C16&"_"&D16&"_"&E16 -> 1_男_14 | C16: 1 | D16: 男 | E16: 14 | F16: 32746.8 | G16: 31
B17: =C17&"_"&D17&"_"&E17 -> 1_男_15 | C17: 1 | D17: 男 | E17: 15 | F17: 32764.5 | G17: 31
... B399: =C399&"_"&D399&"_"&E399 -> 10_女_45 | C399: 10 | D399: 女 | E399: 45 | F399: 4366.9 | G399: 229
B400: =C400&"_"&D400&"_"&E400 -> __
B401: =C401&"_"&D401&"_"&E401 -> __
B402: =C402&"_"&D402&"_"&E402 -> __
B403: =C403&"_"&D403&"_"&E403 -> __
B404: =C404&"_"&D404&"_"&E404 -> __
B405: =C405&"_"&D405&"_"&E405 -> __
B406: =C406&"_"&D406&"_"&E406 -> __
B407: =C407&"_"&D407&"_"&E407 -> __
B408: =C408&"_"&D408&"_"&E408 -> __
B409: =C409&"_"&D409&"_"&E409 -> __
B410: =C410&"_"&D410&"_"&E410 -> __
B411: =C411&"_"&D411&"_"&E411 -> __
... B747: =C747&"_"&D747&"_"&E747 -> __

Sheet 现价表
C1: PPP | D1: SEX | E1: AGE | F1: 1 | G1: 2 | H1: 3 | I1: 4 | J1: 5 | K1: 6 | L1: 7 | M1: 8 | N1: 9 | O1: 10 | P1: 11 | Q1: 12 | R1: 13 | S1: 14 | T1: 15 | U1: 16 | V1: 17 | W1: 18 | X1: 19 | Y1: 20 | Z1: 21 | AA1: 22 | AB1: 23 | AC1: 24 | AD1: 25 | AE1: 26 | AF1: 27 | AG1: 28 | AH1: 29 | AI1: 30 | AJ1: 31 | AK1: 32 | AL1: 33 | AM1: 34 | AN1: 35 | AO1: 36 | AP1: 37 | AQ1: 38 | AR1: 39 | AS1: 40 | AT1: 41 | AU1: 42 | AV1: 43 | AW1: 44 | AX1: 45 | AY1: 46 | AZ1: 47 | BA1: 48 | BB1: 49 | BC1: 50 | BD1: 51 | BE1: 52 | BF1: 53 | BG1: 54 | BH1: 55 | BI1: 56 | BJ1: 57 | BK1: 58 | BL1: 59 | BM1: 60 | BN1: 61 | BO1: 62 | BP1: 63 | BQ1: 64 | BR1: 65 | BS1: 66 | BT1: 67 | BU1: 68 | BV1: 69 | BW1: 70 | BX1: 71 | BY1: 72 | BZ1: 73 | CA1: 74 | CB1: 75 | CC1: 76 | CD1: 77 | CE1: 78 | CF1: 79 | CG1: 80 | CH1: 81 | CI1: 82 | CJ1: 83 | CK1: 84 | CL1: 85 | CM1: 86 | CN1: 87 | CO1: 88 | CP1: 89 | CQ1: 90 | CR1: 91 | CS1: 92 | CT1: 93 | CU1: 94 | CV1: 95 | CW1: 96 | CX1: 97 | CY1: 98 | CZ1: 99 | DA1: 100 | DB1: 101 | DC1: 102 | DD1: 103 | DE1: 104 | DF1: 105 | DG1: 106
B2: =C2&"_"&D2&"_"&E2 -> 1_男_0 | C2: 1 | D2: 男 | E2: 0 | F2: 17891.9 | G2: 18779.7 | H2: 19713.9 | I2: 20696 | J2: 20728.2 | K2: 20762.3 | L2: 20798.3 | M2: 20836.2 | N2: 20876 | O2: 20917.8 | P2: 20961.6 | Q2: 21007.4 | R2: 21055.2 | S2: 21105.3 | T2: 21157.7 | U2: 21212.4 | V2: 21269.7 | W2: 21329.7 | X2: 21392.6 | Y2: 21458.5 | Z2: 21527.5 | AA2: 21599.8 | AB2: 21675.6 | AC2: 21755.1 | AD2: 21838.3 | AE2: 21925.6 | AF2: 22017 | AG2: 22112.7 | AH2: 22213 | AI2: 22318.1 | AJ2: 22428.1 | AK2: 22543.2 | AL2: 22663.8 | AM2: 22790 | AN2: 22922.1 | AO2: 23060.3 | AP2: 23204.9 | AQ2: 23356.1 | AR2: 23514.4 | AS2: 23680 | AT2: 23853.2 | AU2: 24034.4 | AV2: 24223.9 | AW2: 24422.1 | AX2: 24629.5 | AY2: 24846.5 | AZ2: 25073.6 | BA2: 25311.2 | BB2: 25560 | BC2: 25820.5 | BD2: 26093.3 | BE2: 26379.1 | BF2: 26678.7 | BG2: 26992.9 | BH2: 27322.5 | BI2: 27668.5 | BJ2: 28031.9 | BK2: 28413.7 | BL2: 28815.3 | BM2: 28238 | BN2: 0 | BO2: 0 | BP2: 0 | BQ2: 0 | BR2: 0 | BS2: 0 | BT2: 0 | BU2: 0 | BV2: 0 | BW2: 0 | BX2: 0 | BY2: 0 | BZ2: 0 | CA2: 0 | CB2: 0 | CC2: 0 | CD2: 0 | CE2: 0 | CF2: 0 | CG2: 0 | CH2: 0 | CI2: 0 | CJ2: 0 | CK2: 0 | CL2: 0 | CM2: 0 | CN2: 0 | CO2: 0 | CP2: 0 | CQ2: 0 | CR2: 0 | CS2: 0 | CT2: 0 | CU2: 0 | CV2: 0 | CW2: 0 | CX2: 0 | CY2: 0 | CZ2: 0 | DA2: 0 | DB2: 0 | DC2: 0 | DD2: 0 | DE2: 0 | DF2: 0 | DG2: 0
B3: =C3&"_"&D3&"_"&E3 -> 1_男_1 | C3: 1 | D3: 男 | E3: 1 | F3: 17916.7 | G3: 18807.4 | H3: 19744 | I3: 20728.3 | J3: 20762.4 | K3: 20798.4 | L3: 20836.3 | M3: 20876.2 | N3: 20918 | O3: 20961.7 | P3: 21007.5 | Q3: 21055.4 | R3: 21105.5 | S3: 21157.8 | T3: 21212.6 | U3: 21269.9 | V3: 21329.9 | W3: 21392.8 | X3: 21458.7 | Y3: 21527.7 | Z3: 21600 | AA3: 21675.9 | AB3: 21755.3 | AC3: 21838.6 | AD3: 21925.8 | AE3: 22017.2 | AF3: 22113 | AG3: 22213.3 | AH3: 22318.4 | AI3: 22428.4 | AJ3: 22543.5 | AK3: 22664.1 | AL3: 22790.3 | AM3: 22922.4 | AN3: 23060.6 | AO3: 23205.2 | AP3: 23356.5 | AQ3: 23514.8 | AR3: 23680.4 | AS3: 23853.6 | AT3: 24034.7 | AU3: 24224.3 | AV3: 24422.5 | AW3: 24629.9 | AX3: 24846.9 | AY3: 25074 | AZ3: 25311.6 | BA3: 25560.4 | BB3: 25820.8 | BC3: 26093.6 | BD3: 26379.4 | BE3: 26679 | BF3: 26993.2 | BG3: 27322.7 | BH3: 27668.7 | BI3: 28032 | BJ3: 28413.9 | BK3: 28815.4 | BL3: 28238 | BM3: 0 | BN3: 0 | BO3: 0 | BP3: 0 | BQ3: 0 | BR3: 0 | BS3: 0 | BT3: 0 | BU3: 0 | BV3: 0 | BW3: 0 | BX3: 0 | BY3: 0 | BZ3: 0 | CA3: 0 | CB3: 0 | CC3: 0 | CD3: 0 | CE3: 0 | CF3: 0 | CG3: 0 | CH3: 0 | CI3: 0 | CJ3: 0 | CK3: 0 | CL3: 0 | CM3: 0 | CN3: 0 | CO3: 0 | CP3: 0 | CQ3: 0 | CR3: 0 | CS3: 0 | CT3: 0 | CU3: 0 | CV3: 0 | CW3: 0 | CX3: 0 | CY3: 0 | CZ3: 0 | DA3: 0 | DB3: 0 | DC3: 0 | DD3: 0 | DE3: 0 | DF3: 0 | DG3: 0
